Workbook

Sheet 工作表1
A3: 門市 | B3: 計數 - 機型 | F3: 列標籤 | G3: 計數 - 機型
A4: 一中 | B4: 4 | C4: =VLOOKUP(A:A,#REF!,2,0) -> #VALUE! | D4: =GETPIVOTDATA("機型",$A$3,"門市","一中")=C4 -> #VALUE! | F4: 一中 | G4: 4 | H4: =VLOOKUP(F:F,#REF!,2,0) -> #VALUE! | I4: =G4=H4 -> #VALUE!
A5: 七堵 | B5: 5 | C5: 5 | D5: =GETPIVOTDATA("機型",$A$3,"門市","七堵")=C5 -> 1 | F5: 七堵 | G5: 5 | H5: 5 | I5: =G5=H5 -> 1
A6: 二水 | B6: 4 | C6: =VLOOKUP(A:A,#REF!,2,0) -> #VALUE! | D6: =GETPIVOTDATA("機型",$A$3,"門市","七堵")=C6 -> #VALUE! | F6: 二水 | G6: 4 | H6: =VLOOKUP(F:F,#REF!,2,0) -> #VALUE! | I6: =G6=H6 -> #VALUE!
A7: 二林 | B7: 6 | C7: =VLOOKUP(A:A,#REF!,2,0) -> #VALUE! | D7: =GETPIVOTDATA("機型",$A$3,"門市","七堵")=C7 -> #VALUE! | F7: 二林 | G7: 6 | H7: =VLOOKUP(F:F,#REF!,2,0) -> #VALUE! | I7: =G7=H7 -> #VALUE!
A8: 二崙 | B8: 4 | C8: =VLOOKUP(A:A,#REF!,2,0) -> #VALUE! | D8: =GETPIVOTDATA("機型",$A$3,"門市","七堵")=C8 -> #VALUE! | F8: 二崙 | G8: 4 | H8: =VLOOKUP(F:F,#REF!,2,0) -> #VALUE! | I8: =G8=H8 -> #VALUE!
A9: 八里 | B9: 2 | C9: =VLOOKUP(A:A,#REF!,2,0) -> #VALUE! | D9: =GETPIVOTDATA("機型",$A$3,"門市","七堵")=C9 -> #VALUE! | F9: 八里 | G9: 2 | H9: =VLOOKUP(F:F,#REF!,2,0) -> #VALUE! | I9: =G9=H9 -> #VALUE!
A10: 八德 | B10: 1 | C10: =VLOOKUP(A:A,#REF!,2,0) -> #VALUE! | D10: =GETPIVOTDATA("機型",$A$3,"門市","七堵")=C10 -> #VALUE! | F10: 八德 | G10: 1 | H10: =VLOOKUP(F:F,#REF!,2,0) -> #VALUE! | I10: =G10=H10 -> #VALUE!
A11: 八德大湳 | B11: 5 | C11: =VLOOKUP(A:A,#REF!,2,0) -> #VALUE! | D11: =GETPIVOTDATA("機型",$A$3,"門市","七堵")=C11 -> #VALUE! | F11: 八德大湳 | G11: 5 | H11: =VLOOKUP(F:F,#REF!,2,0) -> #VALUE! | I11: =G11=H11 -> #VALUE!
A12: 力行 | B12: 2 | C12: =VLOOKUP(A:A,#REF!,2,0) -> #VALUE! | D12: =GETPIVOTDATA("機型",$A$3,"門市","七堵")=C12 -> #VALUE! | F12: 力行 | G12: 2 | H12: =VLOOKUP(F:F,#REF!,2,0) -> #VALUE! | I12: =G12=H12 -> #VALUE!
A13: 力行辦公室 | B13: 1 | C13: 1 | D13: =GETPIVOTDATA("機型",$A$3,"門市","七堵")=C13 -> 0 | F13: 力行辦公室 | G13: 1 | H13: 1 | I13: =G13=H13 -> 1
A14: 十甲 | B14: 4 | C14: =VLOOKUP(A:A,#REF!,2,0) -> #VALUE! | D14: =GETPIVOTDATA("機型",$A$3,"門市","七堵")=C14 -> #VALUE! | F14: 十甲 | G14: 4 | H14: =VLOOKUP(F:F,#REF!,2,0) -> #VALUE! | I14: =G14=H14 -> #VALUE!
A15: 十全 | B15: 1 | C15: =VLOOKUP(A:A,#REF!,2,0) -> #VALUE! | D15: =GETPIVOTDATA("機型",$A$3,"門市","七堵")=C15 -> #VALUE! | F15: 十全 | G15: 1 | H15: =VLOOKUP(F:F,#REF!,2,0) -> #VALUE! | I15: =G15=H15 -> #VALUE!
A16: 三多 | B16: 7 | C16: =VLOOKUP(A:A,#REF!,2,0) -> #VALUE! | D16: =GETPIVOTDATA("機型",$A$3,"門市","七堵")=C16 -> #VALUE! | F16: 三多 | G16: 7 | H16: =VLOOKUP(F:F,#REF!,2,0) -> #VALUE! | I16: =G16=H16 -> #VALUE!
A17: 三芝 | B17: 2 | C17: =VLOOKUP(A:A,#REF!,2,0) -> #VALUE! | D17: =GETPIVOTDATA("機型",$A$3,"門市","七堵")=C17 -> #VALUE! | F17: 三芝 | G17: 2 | H17: =VLOOKUP(F:F,#REF!,2,0) -> #VALUE! | I17: =G17=H17 -> #VALUE!
A18: 三星 | B18: 3 | C18: =VLOOKUP(A:A,#REF!,2,0) -> #VALUE! | D18: =GETPIVOTDATA("機型",$A$3,"門市","七堵")=C18 -> #VALUE! | F18: 三星 | G18: 3 | H18: =VLOOKUP(F:F,#REF!,2,0) -> #VALUE! | I18: =G18=H18 -> #VALUE!
A19: 三重 | B19: 21 | C19: =VLOOKUP(A:A,#REF!,2,0) -> #VALUE! | D19: =GETPIVOTDATA("機型",$A$3,"門市","七堵")=C19 -> #VALUE! | F19: 三重 | G19: 21 | H19: =VLOOKUP(F:F,#REF!,2,0) -> #VALUE! | I19: =G19=H19 -> #VALUE!
A20: 三重正義 | B20: 5 | C20: =VLOOKUP(A:A,#REF!,2,0) -> #VALUE! | D20: =GETPIVOTDATA("機型",$A$3,"門市","七堵")=C20 -> #VALUE! | F20: 三重正義 | G20: 5 | H20: =VLOOKUP(F:F,#REF!,2,0) -> #VALUE! | I20: =G20=H20 -> #VALUE!
A21: 三峽 | B21: 2 | C21: =VLOOKUP(A:A,#REF!,2,0) -> #VALUE! | D21: =GETPIVOTDATA("機型",$A$3,"門市","七堵")=C21 -> #VALUE! | F21: 三峽 | G21: 2 | H21: =VLOOKUP(F:F,#REF!,2,0) -> #VALUE! | I21: =G21=H21 -> #VALUE!
A22: 三峽復興 | B22: 3 | C22: =VLOOKUP(A:A,#REF!,2,0) -> #VALUE! | D22: =GETPIVOTDATA("機型",$A$3,"門市","七堵")=C22 -> #VALUE! | F22: 三峽復興 | G22: 3 | H22: =VLOOKUP(F:F,#REF!,2,0) -> #VALUE! | I22: =G22=H22 -> #VALUE!
A23: 三義 | B23: 2 | C23: =VLOOKUP(A:A,#REF!,2,0) -> #VALUE! | D23: =GETPIVOTDATA("機型",$A$3,"門市","七堵")=C23 -> #VALUE! | F23: 三義 | G23: 2 | H23: =VLOOKUP(F:F,#REF!,2,0) -> #VALUE! | I23: =G23=H23 -> #VALUE!
A24: 下營 | B24: 4 | C24: 4 | D24: =GETPIVOTDATA("機型",$A$3,"門市","七堵")=C24 -> 0 | F24: 下營 | G24: 4 | H24: 4 | I24: =G24=H24 -> 1
A25: 口湖 | B25: 1 | C25: 1 | D25: =GETPIVOTDATA("機型",$A$3,"門市","七堵")=C25 -> 0 | F25: 口湖 | G25: 1 | H25: 1 | I25: =G25=H25 -> 1
A26: 土城 | B26: 4 | C26: =VLOOKUP(A:A,#REF!,2,0) -> #VALUE! | D26: =GETPIVOTDATA("機型",$A$3,"門市","七堵")=C26 -> #VALUE! | F26: 土城 | G26: 4 | H26: =VLOOKUP(F:F,#REF!,2,0) -> #VALUE! | I26: =G26=H26 -> #VALUE!
A27: 土庫 | B27: 4 | C27: =VLOOKUP(A:A,#REF!,2,0) -> #VALUE! | D27: =GETPIVOTDATA("機型",$A$3,"門市","七堵")=C27 -> #VALUE! | F27: 土庫 | G27: 4 | H27: =VLOOKUP(F:F,#REF!,2,0) -> #VALUE! | I27: =G27=H27 -> #VALUE!
A28: 士林 | B28: 5 | C28: =VLOOKUP(A:A,#REF!,2,0) -> #VALUE! | D28: =GETPIVOTDATA("機型",$A$3,"門市","七堵")=C28 -> #VALUE! | F28: 士林 | G28: 5 | H28: =VLOOKUP(F:F,#REF!,2,0) -> #VALUE! | I28: =G28=H28 -> #VALUE!
A29: 士林夜市 | B29: 9 | C29: =VLOOKUP(A:A,#REF!,2,0) -> #VALUE! | D29: =GETPIVOTDATA("機型",$A$3,"門市","七堵")=C29 -> #VALUE! | F29: 士林夜市 | G29: 9 | H29: =VLOOKUP(F:F,#REF!,2,0) -> #VALUE! | I29: =G29=H29 -> #VALUE!
A30: 大甲 | B30: 6 | C30: =VLOOKUP(A:A,#REF!,2,0) -> #VALUE! | D30: =GETPIVOTDATA("機型",$A$3,"門市","七堵")=C30 -> #VALUE! | F30: 大甲 | G30: 6 | H30: =VLOOKUP(F:F,#REF!,2,0) -> #VALUE! | I30: =G30=H30 -> #VALUE!
A31: 大同 | B31: 7 | C31: =VLOOKUP(A:A,#REF!,2,0) -> #VALUE! | D31: =GETPIVOTDATA("機型",$A$3,"門市","七堵")=C31 -> #VALUE! | F31: 大同 | G31: 7 | H31: =VLOOKUP(F:F,#REF!,2,0) -> #VALUE! | I31: =G31=H31 -> #VALUE!
A32: 大安 | B32: 11 | C32: =VLOOKUP(A:A,#REF!,2,0) -> #VALUE! | D32: =GETPIVOTDATA("機型",$A$3,"門市","七堵")=C32 -> #VALUE! | F32: 大安 | G32: 11 | H32: =VLOOKUP(F:F,#REF!,2,0) -> #VALUE! | I32: =G32=H32 -> #VALUE!
A33: 大有 | B33: 4 | C33: =VLOOKUP(A:A,#REF!,2,0) -> #VALUE! | D33: =GETPIVOTDATA("機型",$A$3,"門市","七堵")=C33 -> #VALUE! | F33: 大有 | G33: 4 | H33: =VLOOKUP(F:F,#REF!,2,0) -> #VALUE! | I33: =G33=H33 -> #VALUE!
A34: 大竹 | B34: 4 | C34: =VLOOKUP(A:A,#REF!,2,0) -> #VALUE! | D34: =GETPIVOTDATA("機型",$A$3,"門市","七堵")=C34 -> #VALUE! | F34: 大竹 | G34: 4 | H34: =VLOOKUP(F:F,#REF!,2,0) -> #VALUE! | I34: =G34=H34 -> #VALUE!
A35: 大肚 | B35: 3 | C35: =VLOOKUP(A:A,#REF!,2,0) -> #VALUE! | D35: =GETPIVOTDATA("機型",$A$3,"門市","七堵")=C35 -> #VALUE! | F35: 大肚 | G35: 3 | H35: =VLOOKUP(F:F,#REF!,2,0) -> #VALUE! | I35: =G35=H35 -> #VALUE!
A36: 大里 | B36: 5 | C36: =VLOOKUP(A:A,#REF!,2,0) -> #VALUE! | D36: =GETPIVOTDATA("機型",$A$3,"門市","七堵")=C36 -> #VALUE! | F36: 大里 | G36: 5 | H36: =VLOOKUP(F:F,#REF!,2,0) -> #VALUE! | I36: =G36=H36 -> #VALUE!
A37: 大坪林 | B37: 6 | C37: =VLOOKUP(A:A,#REF!,2,0) -> #VALUE! | D37: =GETPIVOTDATA("機型",$A$3,"門市","七堵")=C37 -> #VALUE! | F37: 大坪林 | G37: 6 | H37: =VLOOKUP(F:F,#REF!,2,0) -> #VALUE! | I37: =G37=H37 -> #VALUE!
... A61: 中埔 | B61: 2 | C61: =VLOOKUP(A:A,#REF!,2,0) -> #VALUE! | D61: =GETPIVOTDATA("機型",$A$3,"門市","七堵")=C61 -> #VALUE! | F61: 中埔 | G61: 2 | H61: =VLOOKUP(F:F,#REF!,2,0) -> #VALUE! | I61: =G61=H61 -> #VALUE!
A62: 中興 | B62: 6 | C62: 6 | D62: =GETPIVOTDATA("機型",$A$3,"門市","七堵")=C62 -> 0 | F62: 中興 | G62: 6 | H62: 6 | I62: =G62=H62 -> 1
A63: 中壢 | B63: 19 | C63: =VLOOKUP(A:A,#REF!,2,0) -> #VALUE! | D63: =GETPIVOTDATA("機型",$A$3,"門市","七堵")=C63 -> #VALUE! | F63: 中壢 | G63: 19 | H63: =VLOOKUP(F:F,#REF!,2,0) -> #VALUE! | I63: =G63=H63 -> #VALUE!
A64: 五分埔 | B64: 4 | C64: =VLOOKUP(A:A,#REF!,2,0) -> #VALUE! | D64: =GETPIVOTDATA("機型",$A$3,"門市","七堵")=C64 -> #VALUE! | F64: 五分埔 | G64: 4 | H64: =VLOOKUP(F:F,#REF!,2,0) -> #VALUE! | I64: =G64=H64 -> #VALUE!
A65: 五甲 | B65: 2 | C65: =VLOOKUP(A:A,#REF!,2,0) -> #VALUE! | D65: =GETPIVOTDATA("機型",$A$3,"門市","七堵")=C65 -> #VALUE! | F65: 五甲 | G65: 2 | H65: =VLOOKUP(F:F,#REF!,2,0) -> #VALUE! | I65: =G65=H65 -> #VALUE!
...

Sheet 門市請款明細表
A1: 項次 | B1: 門市 機器 數量 | C1: 機台 數量 | D1: 門市 編碼 | E1: 設備 編碼 | F1: 客編 | G1: 營運別 | H1: 部別 | I1: 門市 | J1: 機型 | K1: 機器序號 | L1: 安裝日期 | M1: 9月 總頁數 | N1: 10月 總頁數 | O1: 10月 列印量 | P1: 10月 列印量 扣除3%誤印率 | Q1: (單)門市列印量 扣除3%誤印率 | R1: 黑色單價 (含稅) | S1: 單台黑色 列印費用 | T1: (單)門市黑色 列印費用 | U1: 9月 總頁數 | V1: 10月 總頁數 | W1: 10月 列印量 | X1: 10月 列印量 扣除3%誤印率 | Y1: (單)門市列印量 扣除3%誤印率 | Z1: 彩色單價 (含稅) | AA1: 單台彩色 列印費用 | AB1: (單)門市彩色 列印費用 | AC1: 備註 | AD1: 10月
AD2: 覆蓋率 | AE2: 碳粉 啪數
A3: =ROW(A1) -> 1 | B3: 01 | C3: 1 | D3: 5 | E3: 5-01 | F3: 5497-02-1A1001 | G3: 營運一處 | H3: 台北一部 | I3: 台北東門 | J3: Apeos C325dw | K3: NC7003734 | L3: 45779 | M3: 236 | N3: 288 | O3: 52 | P3: 50 | R3: =合約與計費!$D$4 -> 0.296 | S3: =ROUND(P3*R3,0) -> 15 | U3: 845 | V3: 1084 | W3: 239 | X3: 232 | Z3: =合約與計費!$E$4 -> 2.8 | AA3: =ROUND(X3*Z3,0) -> 650
A4: =ROW(A2) -> 2 | B4: 02 | C4: 1 | E4: 5-02 | F4: 5497-02-1A1001 | G4: 營運一處 | H4: 台北一部 | I4: 台北東門 | J4: Apeos 4620SDF | K4: YB5000419 | L4: 45779 | M4: 1249 | N4: 1949 | O4: 700 | P4: 679 | R4: =合約與計費!$D$4 -> 0.296 | S4: =ROUND(P4*R4,0) -> 201 | AD4: 0.0548 | AE4: 0.2
A5: =ROW(A3) -> 3 | B5: 03 | C5: 1 | E5: 5-03 | F5: 5497-02-1A1001 | G5: 營運一處 | H5: 台北一部 | I5: 台北東門 | J5: Apeos 4620SDF | K5: YB5000424 | L5: 45779 | M5: 1788 | N5: 2031 | O5: 243 | P5: 236 | R5: =合約與計費!$D$4 -> 0.296 | S5: =ROUND(P5*R5,0) -> 70 | AD5: 0.0577 | AE5: 0.1
A6: =ROW(A4) -> 4 | B6: 04 | C6: 1 | E6: 5-04 | F6: 5497-02-1A1001 | G6: 營運一處 | H6: 台北一部 | I6: 台北東門 | J6: ApeosPrint 4620SDN | K6: YB7000734 | L6: 45779 | M6: 617 | N6: 1377 | O6: 760 | P6: 737 | R6: =合約與計費!$D$4 -> 0.296 | S6: =ROUND(P6*R6,0) -> 218 | AD6: 0.0804 | AE6: 0.1
A7: =ROW(A5) -> 5 | B7: 05 | C7: 1 | E7: 5-05 | F7: 5497-02-1A1001 | G7: 營運一處 | H7: 台北一部 | I7: 台北東門 | J7: ApeosPrint 4620SDN | K7: YB7000737 | L7: 45779 | M7: 9824 | N7: 11610 | O7: 1786 | P7: 1732 | R7: =合約與計費!$D$4 -> 0.296 | S7: =ROUND(P7*R7,0) -> 513 | AD7: 0.0793 | AE7: 0.1
A8: =ROW(A6) -> 6 | B8: 06 | C8: 1 | E8: 5-06 | F8: 5497-02-1A1001 | G8: 營運一處 | H8: 台北一部 | I8: 台北東門 | J8: ApeosPrint 4620SDN | K8: YB7000738 | L8: 45779 | M8: 5363 | N8: 6779 | O8: 1416 | P8: 1374 | R8: =合約與計費!$D$4 -> 0.296 | S8: =ROUND(P8*R8,0) -> 407 | AD8: 0.1144 | AE8: 0.5
A9: =ROW(A7) -> 7 | B9: 07 | C9: 1 | E9: 5-07 | F9: 5497-02-1A1001 | G9: 營運一處 | H9: 台北一部 | I9: 台北東門 | J9: ApeosPrint 4620SDN | K9: YB7000739 | L9: 45779 | M9: 4966 | N9: 6611 | O9: 1645 | P9: 1596 | R9: =合約與計費!$D$4 -> 0.296 | S9: =ROUND(P9*R9,0) -> 472 | AD9: 0.0955 | AE9: 0.6
A10: =ROW(A8) -> 8 | B10: 08 | C10: 1 | E10: 5-08 | F10: 5497-02-1A1001 | G10: 營運一處 | H10: 台北一部 | I10: 台北東門 | J10: ApeosPrint 4620SDN | K10: YB7000741 | L10: 45779 | M10: 282 | N10: 410 | O10: 128 | P10: 124 | R10: =合約與計費!$D$4 -> 0.296 | S10: =ROUND(P10*R10,0) -> 37 | AD10: 0.0976 | AE10: 0.8
A11: =ROW(A9) -> 9 | B11: 09 | C11: 1 | E11: 5-09 | F11: 5497-02-1A1001 | G11: 營運一處 | H11: 台北一部 | I11: 台北東門 | J11: ApeosPrint 4620SDN | K11: YB7000742 | L11: 45779 | M11: 3837 | N11: 5182 | O11: 1345 | P11: 1305 | R11: =合約與計費!$D$4 -> 0.296 | S11: =ROUND(P11*R11,0) -> 386 | AD11: 0.0873 | AE11: 0.1
A12: =ROW(A10) -> 10 | B12: 10 | C12: 1 | E12: 5-10 | F12: 5497-02-1A1001 | G12: 營運一處 | H12: 台北一部 | I12: 台北東門 | J12: ApeosPrint 4620SDN | K12: YB7000743 | L12: 45779 | M12: 4777 | N12: 5804 | O12: 1027 | P12: 996 | R12: =合約與計費!$D$4 -> 0.296 | S12: =ROUND(P12*R12,0) -> 295 | AD12: 0.101 | AE12: 0.9
A13: =ROW(A11) -> 11 | B13: 11 | C13: 1 | E13: 5-11 | F13: 5497-02-1A1001 | G13: 營運一處 | H13: 台北一部 | I13: 台北東門 | J13: ApeosPrint 4620SDN | K13: YB7000744 | L13: 45779 | M13: 12624 | N13: 16106 | O13: 3482 | P13: 3378 | R13: =合約與計費!$D$4 -> 0.296 | S13: =ROUND(P13*R13,0) -> 1000 | AD13: 0.0813 | AE13: 0.7
A14: =ROW(A12) -> 12 | B14: 12 | C14: 1 | E14: 5-12 | F14: 5497-02-1A1001 | G14: 營運一處 | H14: 台北一部 | I14: 台北東門 | J14: ApeosPrint 4620SDN | K14: YB7000745 | L14: 45779 | M14: 2214 | N14: 3318 | O14: 1104 | P14: 1071 | R14: =合約與計費!$D$4 -> 0.296 | S14: =ROUND(P14*R14,0) -> 317 | AD14: 0.0737 | AE14: 0.9
A15: =ROW(A13) -> 13 | B15: 13 | C15: 1 | E15: 5-13 | F15: 5497-02-1A1001 | G15: 營運一處 | H15: 台北一部 | I15: 台北東門 | J15: ApeosPrint 4620SDN | K15: YB7000746 | L15: 45779 | M15: 3868 | N15: 4739 | O15: 871 | P15: 845 | R15: =合約與計費!$D$4 -> 0.296 | S15: =ROUND(P15*R15,0) -> 250 | AD15: 0.0506 | AE15: 0.8
A16: =ROW(A14) -> 14 | B16: 14 | C16: 1 | E16: 5-14 | F16: 5497-02-1A1001 | G16: 營運一處 | H16: 台北一部 | I16: 台北東門 | J16: ApeosPrint 4620SDN | K16: YB7000747 | L16: 45779 | M16: 1503 | N16: 2161 | O16: 658 | P16: 638 | R16: =合約與計費!$D$4 -> 0.296 | S16: =ROUND(P16*R16,0) -> 189 | AD16: 0.0829 | AE16: 0.7
A17: =ROW(A15) -> 15 | B17: 15 | C17: 1 | E17: 5-15 | F17: 5497-02-1A1001 | G17: 營運一處 | H17: 台北一部 | I17: 台北東門 | J17: ApeosPrint 4620SDN | K17: YB7000748 | L17: 45779 | M17: 5562 | N17: 7374 | O17: 1812 | P17: 1758 | R17: =合約與計費!$D$4 -> 0.296 | S17: =ROUND(P17*R17,0) -> 520 | AD17: 0.1075 | AE17: 0.5
A18: =ROW(A16) -> 16 | B18: 16 | C18: 1 | E18: 5-16 | F18: 5497-02-1A1001 | G18: 營運一處 | H18: 台北一部 | I18: 台北東門 | J18: ApeosPrint 4620SDN | K18: YB7000756 | L18: 45779 | M18: 3570 | N18: 4738 | O18: 1168 | P18: 1133 | R18: =合約與計費!$D$4 -> 0.296 | S18: =ROUND(P18*R18,0) -> 335 | AD18: 0.2639 | AE18: 0.5
A19: =ROW(A17) -> 17 | B19: 17 | C19: 1 | E19: 5-17 | F19: 5497-02-1A1001 | G19: 營運一處 | H19: 台北一部 | I19: 台北東門 | J19: ApeosPrint 4620SDN | K19: YB7000770 | L19: 45779 | M19: 4672 | N19: 6424 | O19: 1752 | P19: 1699 | R19: =合約與計費!$D$4 -> 0.296 | S19: =ROUND(P19*R19,0) -> 503 | AD19: 0.0957 | AE19: 0.6
A20: =ROW(A18) -> 18 | B20: 18 | C20: 1 | E20: 5-18 | F20: 5497-02-1A1001 | G20: 營運一處 | H20: 台北一部 | I20: 台北東門 | J20: ApeosPrint 4620SDN | K20: YB7000778 | L20: 45779 | M20: 4826 | N20: 6276 | O20: 1450 | P20: 1407 | Q20: =ROUND(SUM(P3:P20),2) -> 20758 | R20: =合約與計費!$D$4 -> 0.296 | S20: =ROUND(P20*R20,0) -> 416 | T20: =ROUND(SUM(S3:S20),2) -> 6144 | Y20: =ROUND(SUM(X3:X20),2) -> 232 | AB20: =ROUND(SUM(AA3:AA20),2) -> 650 | AD20: 0.1138 | AE20: 0.5
A21: =ROW(A19) -> 19 | B21: 01 | C21: 1 | D21: 8 | E21: 8-01 | F21: 5497-02-1A1002 | G21: 營運一處 | H21: 台北一部 | I21: 台北公館 | J21: Apeos C325dw | K21: NC7003785 | L21: 45779 | M21: 561 | N21: 613 | O21: 52 | P21: 50 | R21: =合約與計費!$D$4 -> 0.296 | S21: =ROUND(P21*R21,0) -> 15 | U21: 284 | V21: 331 | W21: 47 | X21: 46 | Z21: =合約與計費!$E$4 -> 2.8 | AA21: =ROUND(X21*Z21,0) -> 129
A22: =ROW(A20) -> 20 | B22: 02 | C22: 1 | E22: 8-02 | F22: 5497-02-1A1002 | G22: 營運一處 | H22: 台北一部 | I22: 台北公館 | J22: Apeos 4620SDF | K22: YB5000422 | L22: 45779 | M22: 882 | N22: 1004 | O22: 122 | P22: 118 | R22: =合約與計費!$D$4 -> 0.296 | S22: =ROUND(P22*R22,0) -> 35 | AD22: 0.057 | AE22: 0.6
A23: =ROW(A21) -> 21 | B23: 03 | C23: 1 | E23: 8-03 | F23: 5497-02-1A1002 | G23: 營運一處 | H23: 台北一部 | I23: 台北公館 | J23: ApeosPrint 4620SDN | K23: YB7000845 | L23: 45779 | M23: 19207 | N23: 24079 | O23: 4872 | P23: 4726 | R23: =合約與計費!$D$4 -> 0.296 | S23: =ROUND(P23*R23,0) -> 1399 | AD23: 0.1005 | AE23: 0.8
A24: =ROW(A22) -> 22 | B24: 04 | C24: 1 | E24: 8-04 | F24: 5497-02-1A1002 | G24: 營運一處 | H24: 台北一部 | I24: 台北公館 | J24: ApeosPrint 4620SDN | K24: YB7000858 | L24: 45779 | M24: 7038 | N24: 9121 | O24: 2083 | P24: 2021 | R24: =合約與計費!$D$4 -> 0.296 | S24: =ROUND(P24*R24,0) -> 598 | AD24: 0.1093 | AE24: 0.5
A25: =ROW(A23) -> 23 | B25: 05 | C25: 1 | E25: 8-05 | F25: 5497-02-1A1002 | G25: 營運一處 | H25: 台北一部 | I25: 台北公館 | J25: ApeosPrint 4620SDN | K25: YB7000860 | L25: 45779 | M25: 17 | N25: 21 | O25: 4 | P25: 4 | R25: =合約與計費!$D$4 -> 0.296 | S25: =ROUND(P25*R25,0) -> 1 | AD25: 0.3293 | AE25: 0.8
A26: =ROW(A24) -> 24 | B26: 06 | C26: 1 | E26: 8-06 | F26: 5497-02-1A1002 | G26: 營運一處 | H26: 台北一部 | I26: 台北公館 | J26: ApeosPrint 4620SDN | K26: YB7000864 | L26: 45779 | M26: 6895 | N26: 8276 | O26: 1381 | P26: 1340 | R26: =合約與計費!$D$4 -> 0.296 | S26: =ROUND(P26*R26,0) -> 397 | AD26: 0.0645 | AE26: 0.5
A27: =ROW(A25) -> 25 | B27: 07 | C27: 1 | E27: 8-07 | F27: 5497-02-1A1002 | G27: 營運一處 | H27: 台北一部 | I27: 台北公館 | J27: ApeosPrint 4620SDN | K27: YB7000866 | L27: 45779 | M27: 14884 | N27: 17915 | O27: 3031 | P27: 2940 | Q27: =ROUND(SUM(P21:P27),2) -> 11199 | R27: =合約與計費!$D$4 -> 0.296 | S27: =ROUND(P27*R27,0) -> 870 | T27: =ROUND(SUM(S21:S27),2) -> 3315 | Y27: =ROUND(SUM(X21:X27),2) -> 46 | AB27: =ROUND(SUM(AA21:AA27),2) -> 129 | AD27: 0.1012 | AE27: 1
A28: =ROW(A26) -> 26 | B28: 01 | C28: 1 | D28: 9 | E28: 9-01 | F28: 5497-02-1A1003 | G28: 營運一處 | H28: 台北一部 | I28: 台北木新 | J28: Apeos C325dw | K28: NC7003560 | L28: 45744 | M28: 88 | N28: 261 | O28: 173 | P28: 168 | R28: =合約與計費!$D$4 -> 0.296 | S28: =ROUND(P28*R28,0) -> 50 | U28: 346 | V28: 415 | W28: 69 | X28: 67 | Z28: =合約與計費!$E$4 -> 2.8 | AA28: =ROUND(X28*Z28,0) -> 188
A29: =ROW(A27) -> 27 | B29: 02 | C29: 1 | E29: 9-02 | F29: 5497-02-1A1003 | G29: 營運一處 | H29: 台北一部 | I29: 台北木新 | J29: Apeos 4620SDF | K29: YB5000293 | L29: 45744 | M29: 1562 | N29: 1690 | O29: 128 | P29: 124 | R29: =合約與計費!$D$4 -> 0.296 | S29: =ROUND(P29*R29,0) -> 37 | AD29: 0.0671 | AE29: 0.1
A30: =ROW(A28) -> 28 | B30: 03 | C30: 1 | E30: 9-03 | F30: 5497-02-1A1003 | G30: 營運一處 | H30: 台北一部 | I30: 台北木新 | J30: HP 4003dn | K30: PHLKP01612 | L30: 45744 | M30: 1545 | N30: 1741 | O30: 196 | P30: 190 | R30: =合約與計費!$D$4 -> 0.296 | S30: =ROUND(P30*R30,0) -> 56
A31: =ROW(A29) -> 29 | B31: 04 | C31: 1 | E31: 9-04 | F31: 5497-02-1A1003 | G31: 營運一處 | H31: 台北一部 | I31: 台北木新 | J31: HP 4003dn | K31: PHLKP02866 | L31: 45744 | M31: 14354 | N31: 16473 | O31: 2119 | P31: 2055 | R31: =合約與計費!$D$4 -> 0.296 | S31: =ROUND(P31*R31,0) -> 608
A32: =ROW(A30) -> 30 | B32: 05 | C32: 1 | E32: 9-05 | F32: 5497-02-1A1003 | G32: 營運一處 | H32: 台北一部 | I32: 台北木新 | J32: HP 4003dn | K32: PHLKP02876 | L32: 45744 | M32: 16805 | N32: 19162 | O32: 2357 | P32: 2286 | Q32: =ROUND(SUM(P28:P32),2) -> 4823 | R32: =合約與計費!$D$4 -> 0.296 | S32: =ROUND(P32*R32,0) -> 677 | T32: =ROUND(SUM(S28:S32),2) -> 1428 | Y32: =ROUND(SUM(X28:X32),2) -> 67 | AB32: =ROUND(SUM(AA28:AA32),2) -> 188
A33: =ROW(A31) -> 31 | B33: 01 | C33: 1 | D33: 10 | E33: 10-01 | F33: 5497-02-1A1004 | G33: 營運一處 | H33: 台北一部 | I33: 台北師大 | J33: Apeos C325dw | K33: NC7003635 | L33: 45761 | M33: 1501 | N33: 1781 | O33: 280 | P33: 272 | R33: =合約與計費!$D$4 -> 0.296 | S33: =ROUND(P33*R33,0) -> 81 | U33: 542 | V33: 752 | W33: 210 | X33: 204 | Z33: =合約與計費!$E$4 -> 2.8 | AA33: =ROUND(X33*Z33,0) -> 571
A34: =ROW(A32) -> 32 | B34: 02 | C34: 1 | E34: 10-02 | F34: 5497-02-1A1004 | G34: 營運一處 | H34: 台北一部 | I34: 台北師大 | J34: Apeos 4620SDF | K34: YB5000330 | L34: 45761 | M34: 622 | N34: 750 | O34: 128 | P34: 124 | R34: =合約與計費!$D$4 -> 0.296 | S34: =ROUND(P34*R34,0) -> 37
A35: =ROW(A33) -> 33 | B35: 03 | C35: 1 | E35: 10-03 | F35: 5497-02-1A1004 | G35: 營運一處 | H35: 台北一部 | I35: 台北師大 | J35: HP 4003dn | K35: PHLKQ02073 | L35: 45761 | M35: 23975 | N35: 30501 | O35: 6526 | P35: 6330 | R35: =合約與計費!$D$4 -> 0.296 | S35: =ROUND(P35*R35,0) -> 1874
A36: =ROW(A34) -> 34 | B36: 04 | C36: 1 | E36: 10-04 | F36: 5497-02-1A1004 | G36: 營運一處 | H36: 台北一部 | I36: 台北師大 | J36: HP 4003dn | K36: PHLKQ02075 | L36: 45761 | M36: 24955 | N36: 30917 | O36: 5962 | P36: 5783 | R36: =合約與計費!$D$4 -> 0.296 | S36: =ROUND(P36*R36,0) -> 1712
A37: =ROW(A35) -> 35 | B37: 05 | C37: 1 | E37: 10-05 | F37: 5497-02-1A1004 | G37: 營運一處 | H37: 台北一部 | I37: 台北師大 | J37: HP 4003dn | K37: PHLKQ02078 | L37: 45761 | M37: 3871 | N37: 4941 | O37: 1070 | P37: 1038 | Q37: =ROUND(SUM(P33:P37),2) -> 13547 | R37: =合約與計費!$D$4 -> 0.296 | S37: =ROUND(P37*R37,0) -> 307 | T37: =ROUND(SUM(S33:S37),2) -> 4011 | Y37: =ROUND(SUM(X33:X37),2) -> 204 | AB37: =ROUND(SUM(AA33:AA37),2) -> 571
A38: =ROW(A36) -> 36 | B38: 01 | C38: 1 | D38: 11 | E38: 11-01 | F38: 5497-02-1A1005 | G38: 營運一處 | H38: 台北一部 | I38: 景文 | J38: Apeos C325dw | K38: NC7003517 | L38: 45744 | M38: 128 | N38: 155 | O38: 27 | P38: 26 | R38: =合約與計費!$D$4 -> 0.296 | S38: =ROUND(P38*R38,0) -> 8 | U38: 164 | V38: 196 | W38: 32 | X38: 31 | Z38: =合約與計費!$E$4 -> 2.8 | AA38: =ROUND(X38*Z38,0) -> 87
A39: =ROW(A37) -> 37 | B39: 02 | C39: 1 | E39: 11-02 | F39: 5497-02-1A1005 | G39: 營運一處 | H39: 台北一部 | I39: 景文 | J39: Apeos 4620SDF | K39: YB5000277 | L39: 45744 | M39: 470 | N39: 492 | O39: 22 | P39: 21 | R39: =合約與計費!$D$4 -> 0.296 | S39: =ROUND(P39*R39,0) -> 6 | AD39: 0.0692 | AE39: 0.8
A40: =ROW(A38) -> 38 | B40: 03 | C40: 1 | E40: 11-03 | F40: 5497-02-1A1005 | G40: 營運一處 | H40: 台北一部 | I40: 景文 | J40: HP 4003dn | K40: PHLKP01602 | L40: 45744 | M40: 1222 | N40: 1341 | O40: 119 | P40: 115 | R40: =合約與計費!$D$4 -> 0.296 | S40: =ROUND(P40*R40,0) -> 34
...

Sheet 撤機門市
A1: 項次 | B1: 門市 機器 數量 | C1: 機台 數量 | D1: 門市 編碼 | E1: 設備 編碼 | F1: 客編 | G1: 營運別 | H1: 部別 | I1: 門市 | J1: 機型 | K1: 機器序號 | L1: 安裝日期 | M1: 1~6月 列印量 扣除3%誤印率 | N1: 黑色 | V1: 1~6月 列印量 扣除3%誤印率 | W1: 彩色 | AE1: 備註 | AF1: 1-6月 | AH1: 7月
N2: 初始 總頁數 | O2: 本月 總頁數 | P2: 7月 列印量 | Q2: 7月 列印量 扣除3%誤印率 | R2: (單)門市列印量 扣除3%誤印率 | S2: 黑色單價 (含稅) | T2: 單台黑色 列印費用 | U2: (單)門市黑色 列印費用 | W2: 初始 總頁數 | X2: 本月 總頁數 | Y2: 7月 列印量 | Z2: 7月 列印量 扣除3%誤印率 | AA2: (單)門市列印量 扣除3%誤印率 | AB2: 彩色單價 (含稅) | AC2: 單台彩色 列印費用 | AD2: (單)門市彩色 列印費用 | AF2: 覆蓋率 | AG2: 碳粉 啪數 | AH2: 覆蓋率 | AI2: 碳粉 啪數
A3: 1163 | B3: 01 | C3: 1 | D3: 129 | E3: 129-01 | F3: 5497-02-4N1001 | G3: 營運四處 | H3: 彰化一部 | I3: 天后 | J3: HP 4003dn | K3: PHLKP01463 | L3: 45743 | M3: 758.54 | N3: 782 | P3: =O3-N3 -> -782 | Q3: =ROUND(P3*0.97,2) -> -758.54 | S3: =合約與計費!$D$4 -> 0.296 | T3: =ROUND(Q3*S3,0) -> -225 | V3: 0 | Y3: =X3-W3 -> 0 | Z3: =ROUND(Y3*0.97,2) -> 0 | AB3: =合約與計費!$E$4 -> 2.8
A4: 1164 | B4: 02 | C4: 1 | E4: 129-02 | F4: 5497-02-4N1001 | G4: 營運四處 | H4: 彰化一部 | I4: 天后 | J4: HP 4003dn | K4: PHLKP01484 | L4: 45743 | M4: 1531.63 | N4: 1579 | P4: =O4-N4 -> -1579 | Q4: =ROUND(P4*0.97,2) -> -1531.63 | S4: =合約與計費!$D$4 -> 0.296 | T4: =ROUND(Q4*S4,0) -> -453 | V4: 0 | Y4: =X4-W4 -> 0 | Z4: =ROUND(Y4*0.97,2) -> 0 | AB4: =合約與計費!$E$4 -> 2.8
A5: 1165 | B5: 03 | C5: 1 | E5: 129-03 | F5: 5497-02-4N1001 | G5: 營運四處 | H5: 彰化一部 | I5: 天后 | J5: Apeos 4620SDF | K5: YB5000307 | L5: 45743 | M5: 37.83 | N5: 39 | P5: =O5-N5 -> -39 | Q5: =ROUND(P5*0.97,2) -> -37.83 | S5: =合約與計費!$D$4 -> 0.296 | T5: =ROUND(Q5*S5,0) -> -11 | V5: 0 | Y5: =X5-W5 -> 0 | Z5: =ROUND(Y5*0.97,2) -> 0 | AB5: =合約與計費!$E$4 -> 2.8 | AF5: 0.0241 | AG5: 1
A6: 1166 | B6: 04 | C6: 1 | E6: 129-04 | F6: 5497-02-4N1001 | G6: 營運四處 | H6: 彰化一部 | I6: 天后 | J6: Apeos C325dw | K6: NC7003353 | L6: 45743 | M6: 80.51 | N6: 83 | P6: =O6-N6 -> -83 | Q6: =ROUND(P6*0.97,2) -> -80.51 | R6: =ROUND(SUM(Q3:Q6),2) -> -2408.51 | S6: =合約與計費!$D$4 -> 0.296 | T6: =ROUND(Q6*S6,0) -> -24 | U6: =ROUND(SUM(T3:T6),2) -> -713 | V6: 10.67 | W6: 11 | Y6: =X6-W6 -> -11 | Z6: =ROUND(Y6*0.97,2) -> -10.67 | AA6: =ROUND(SUM(Z3:Z6),2) -> -10.67 | AB6: =合約與計費!$E$4 -> 2.8 | AC6: =ROUND(Z6*AB6,0) -> -30 | AD6: =ROUND(SUM(AC3:AC6),2) -> -30

Sheet 辦公室請款明細表
A1: 項次 | B1: 門市 機器 數量 | C1: 機台 數量 | D1: 門市 編碼 | E1: 設備 編碼 | F1: 客編 | G1: 營運別 | H1: 部別 | I1: 門市 | J1: 機型 | K1: 機器序號 | L1: 安裝日期 | M1: 黑色 | AC1: 彩色 | AS1: 備註 | AT1: 1-6月 | AV1: 7月 | AX1: 8月 | AZ1: 9月
M2: 初始 總頁數 | N2: 1-6月 總頁數 | O2: 1-6月 列印量 | P2: 1-6月 列印量 扣除3%誤印率 | Q2: 7月 總頁數 | R2: 7月 列印量 | S2: 7月 列印量 扣除3%誤印率 | T2: 8月 總頁數 | U2: 8月 列印量 | V2: 8月 列印量 扣除3%誤印率 | W2: 本月 總頁數 | X2: 9月 列印量 | Y2: 9月 列印量 扣除3%誤印率 | Z2: 黑色單價 (含稅) | AA2: 單台黑色 列印費用 | AB2: (單)門市黑色 列印費用 | AC2: 初始 總頁數 | AD2: 1-6月 總頁數 | AE2: 1-6月 列印量 | AF2: 1-6月 列印量 扣除3%誤印率 | AG2: 7月 總頁數 | AH2: 7月 列印量 | AI2: 7月 列印量 扣除3%誤印率 | AJ2: 8月 總頁數 | AK2: 8月 列印量 | AL2: 8月 列印量 扣除3%誤印率 | AM2: 本月 總頁數 | AN2: 9月 列印量 | AO2: 9月 列印量 扣除3%誤印率 | AP2: 彩色單價 (含稅) | AQ2: 單台彩色 列印費用 | AR2: (單)門市彩色 列印費用 | AT2: 覆蓋率 | AU2: 碳粉 啪數 | AV2: 覆蓋率 | AW2: 碳粉 啪數 | AX2: 覆蓋率 | AY2: 碳粉 啪數 | AZ2: 覆蓋率 | BA2: 碳粉 啪數
A3: 1 | B3: 01 | C3: 1 | D3: 188 | E3: 188-01 | F3: 5497-02-7S4002 | G3: 通路行銷處 | H3: 管理三部 | I3: 高雄辦公室 | J3: Apeos C325dw | K3: NC7003615 | L3: 45772 | N3: 105 | O3: =N3-M3 -> 105 | P3: =ROUND(O3*0.97,2) -> 101.85 | Q3: 370 | R3: =Q3-M3 -> 370 | S3: =ROUND(R3*0.97,2) -> 358.9 | T3: 450 | U3: =T3-Q3 -> 80 | V3: =ROUND(U3*0.97,0) -> 78 | W3: 546 | X3: =W3-T3 -> 96 | Y3: =ROUND(X3*0.97,0) -> 93 | Z3: =合約與計費!$D$4 -> 0.296 | AA3: =ROUND(Y3*Z3,0) -> 28 | AD3: 59 | AE3: =AD3-AC3 -> 59 | AF3: =ROUND(AE3*0.97,2) -> 57.23 | AG3: 100 | AH3: =AG3-AC3 -> 100 | AI3: =ROUND(AH3*0.97,2) -> 97 | AJ3: 122 | AK3: =AJ3-AG3 -> 22 | AL3: =ROUND(AK3*0.97,0) -> 21 | AM3: 222 | AN3: =AM3-AJ3 -> 100 | AO3: =ROUND(AN3*0.97,0) -> 97 | AP3: =合約與計費!$E$4 -> 2.8 | AQ3: =ROUND(AO3*AP3,0) -> 272 | AU3: =ROUND(AT3*0.97,2) -> 0
R4: =Q3-N3-R3 -> -105 | U4: =Q3-N3-R3 -> -105 | V4: =ROUND(U4*0.97,0) -> -102 | X4: =Q3-N3-R3+U3 -> -25 | Y4: =ROUND(X4*0.97,0) -> -24 | Z4: =合約與計費!$D$4 -> 0.296 | AA4: =ROUND(Y4*Z4,0) -> -7 | AB4: =SUM(AA3:AA4) -> 21 | AH4: =AG3-AD3-AH3 -> -59 | AK4: =AG3-AD3-AH3+AK3 -> -37 | AL4: =ROUND(AK4*0.97,0) -> -36 | AN4: =AG3-AD3-AH3+AK3 -> -37 | AO4: =ROUND(AN4*0.97,0) -> -36 | AP4: =合約與計費!$E$4 -> 2.8 | AQ4: =ROUND(AO4*AP4,0) -> -101 | AR4: =SUM(AQ3:AQ4) -> 171
A5: 2 | B5: 01 | C5: 1 | D5: 212 | E5: 212-01 | F5: 5497-02-7S4001 | G5: 通路行銷處 | H5: 管理三部 | I5: 力行辦公室 | J5: Apeos 4620SDF | K5: YB5000450 | L5: 45769 | N5: 2709 | O5: =N5-M5 -> 2709 | P5: =ROUND(O5*0.97,2) -> 2627.73 | Q5: 3380 | R5: =Q5-M5 -> 3380 | S5: =ROUND(R5*0.97,2) -> 3278.6 | T5: 5099 | U5: =T5-Q5 -> 1719 | V5: =ROUND(U5*0.97,0) -> 1667 | W5: 5629 | X5: =W5-T5 -> 530 | Y5: =ROUND(X5*0.97,0) -> 514 | Z5: =合約與計費!$D$4 -> 0.296 | AA5: =ROUND(Y5*Z5,0) -> 152 | AE5: =AD5-AC5 -> 0 | AF5: =ROUND(AE5*0.97,2) -> 0 | AH5: =AG5-AC5 -> 0 | AI5: =ROUND(AH5*0.97,2) -> 0 | AK5: =AJ5-AG5 -> 0 | AL5: =ROUND(AK5*0.97,2) -> 0 | AN5: =AM5-AG5 -> 0 | AO5: =ROUND(AN5*0.97,2) -> 0 | AP5: =合約與計費!$E$4 -> 2.8 | AQ5: =ROUND(AO5*AP5,0) -> 0 | AT5: 0.0603 | AU5: 1 | AV5: 0.065 | AW5: 0.9 | AX5: 0.069 | AY5: 0.8 | AZ5: 0.07 | BA5: 0.7
R6: =Q5-N5-R5 -> -2709 | U6: =Q5-N5-R5 -> -2709 | V6: =ROUND(U6*0.97,0) -> -2628 | X6: =Q5-N5-R5+U5 -> -990 | Y6: =ROUND(X6*0.97,0) -> -960 | Z6: =合約與計費!$D$4 -> 0.296 | AA6: =ROUND(Y6*Z6,0) -> -284
A7: 3 | B7: 01 | C7: 1 | D7: 185 | E7: 185-02 | F7: 5497-02-7H3001 | G7: 通路營運三處 | H7: 桃三部 | I7: 桃園辦公室(中壢) | J7: Apeos C325dw | K7: NC7003603 | L7: 45758 | N7: 291 | O7: =N7-M7 -> 291 | P7: =ROUND(O7*0.97,2) -> 282.27 | Q7: 371 | R7: =Q7-M7 -> 371 | S7: =ROUND(R7*0.97,2) -> 359.87 | T7: 447 | U7: =T7-Q7 -> 76 | V7: =ROUND(U7*0.97,0) -> 74 | W7: 515 | X7: =W7-T7 -> 68 | Y7: =ROUND(X7*0.97,0) -> 66 | Z7: =合約與計費!$D$4 -> 0.296 | AA7: =ROUND(Y7*Z7,0) -> 20 | AD7: 24 | AE7: =AD7-AC7 -> 24 | AF7: =ROUND(AE7*0.97,2) -> 23.28 | AG7: 27 | AH7: =AG7-AC7 -> 27 | AI7: =ROUND(AH7*0.97,2) -> 26.19 | AJ7: 31 | AK7: =AJ7-AG7 -> 4 | AL7: =ROUND(AK7*0.97,0) -> 4 | AM7: 33 | AN7: =AM7-AJ7 -> 2 | AO7: =ROUND(AN7*0.97,0) -> 2 | AP7: =合約與計費!$E$4 -> 2.8 | AU7: =ROUND(AT7*0.97,2) -> 0
R8: =Q7-N7-R7 -> -291 | U8: =Q7-N7-R7 -> -291 | V8: =ROUND(U8*0.97,0) -> -282 | X8: =Q7-N7-R7+U7 -> -215 | Y8: =ROUND(X8*0.97,0) -> -209 | Z8: =合約與計費!$D$4 -> 0.296 | AA8: =ROUND(Y8*Z8,0) -> -62 | AH8: =AG7-AD7-AH7 -> -24 | AK8: =AG7-AD7-AH7+AK7 -> -20 | AL8: =ROUND(AK8*0.97,0) -> -19 | AN8: =AG7-AD7-AH7+AK7+AN7 -> -18 | AO8: =ROUND(AN8*0.97,0) -> -17 | AP8: =合約與計費!$E$4 -> 2.8
C9: =COUNT(C3:C7) -> 3 | O9: =SUM(O3:O8) -> 3105 | P9: =SUM(P3:P8) -> 3011.85 | R9: =SUM(R3:R8) -> 1016 | S9: =SUM(S3:S8) -> 3997.37 | U9: =SUM(U3:U8) -> -1230 | V9: =SUM(V3:V8) -> -1193 | X9: =SUM(X3:X8) -> -536 | Y9: =SUM(Y3:Y8) -> -520 | AA9: =SUM(AA3:AA7) -> -91 | AE9: =SUM(AE3:AE7) -> 83 | AF9: =SUM(AF3:AF7) -> 80.51 | AH9: =SUM(AH3:AH7) -> 68 | AI9: =SUM(AI3:AI7) -> 123.19 | AK9: =SUM(AK3:AK8) -> -31 | AL9: =SUM(AL3:AL8) -> -30 | AN9: =SUM(AN3:AN8) -> 47 | AO9: =SUM(AO3:AO8) -> 46 | AQ9: =SUM(AQ3:AQ8) -> 171 | AR9: =SUM(AR3:AR8) -> 171

Sheet 請款明細表
B3: 門市/辦公室總計 | C3: =門市請款明細表!D1982&"家" -> 391家 | D3: 黑色列印量 | E3: 彩色列印量
B4: HP 4003dn | C4: =SUMIF(門市請款明細表!$J$1:$J$1981,B4,門市請款明細表!$C$1:$C$1981) -> 502 | D4: =SUMIF(門市請款明細表!$J$3:$J$1981,B4,門市請款明細表!$P$3:$P$1981) -> 584964
B5: ApeosPrint 4620SDN | C5: =SUMIF(門市請款明細表!$J$1:$J$1981,B5,門市請款明細表!$C$1:$C$1981) -> 789 | D5: =SUMIF(門市請款明細表!$J$3:$J$1981,B5,門市請款明細表!$P$3:$P$1981) -> 924270
B6: Apeos 4620SDF | C6: =SUMIF(門市請款明細表!$J$1:$J$1981,B6,門市請款明細表!$C$1:$C$1981) -> 306 | D6: =SUMIF(門市請款明細表!$J$3:$J$1981,B6,門市請款明細表!$P$3:$P$1981) -> 116125
B7: Apeos C325dw | C7: =SUMIF(門市請款明細表!$J$1:$J$1981,B7,門市請款明細表!$C$1:$C$1981) -> 366 | D7: =SUMIF(門市請款明細表!$J$3:$J$1981,B7,門市請款明細表!$P$3:$P$1981) -> 48510 | E7: =SUMIF(門市請款明細表!$J$3:$J$1981,B7,門市請款明細表!$X3:$X1980) -> 21837
B8: 機器台數/列印小計 | C8: =SUM(C4:C7)&"台" -> 1963台 | D8: =ROUND(SUM(D4:D7),0) -> 1673869 | E8: =ROUND(SUM(E4:E7),0) -> 21837
B9: 黑色小計/彩色小計 | D9: =門市請款明細表!S1982 -> 495461 | E9: =門市請款明細表!AA1982 -> 61139
B10: 門市/辦公室小計(含稅) | D10: =SUM(D9:E9) -> 556600
B11: 小計 | D11: =ROUND((D10)/1.05,2) -> 530095.24
B12: 稅金 | D12: =D10-D11 -> 26504.76
B13: 總額 | D13: =ROUND(D11*1.05,0) -> 556600

Sheet 門市機器統計表
A1: 編碼 | B1: 人員 | C1: 門市 | D1: 總計 | E1: HP 4003dn | F1: ApeosPrint 4620SDN | G1: Apeos 4620SDF | H1: Apeos C325dw
A2: 1 | B2: ZV1 | C2: 基隆 | D2: =SUMIF(門市請款明細表!$H$3:$H$1981,$C2,門市請款明細表!$J$3:$J$1981) -> 0 | E2: =SUMIFS(門市請款明細表!$J$3:$J$1981,門市請款明細表!$H$3:$H$1981,$C2,門市請款明細表!$I$3:$I$1981,E$1) -> 0 | F2: =SUMIFS(門市請款明細表!$J$3:$J$1981,門市請款明細表!$H$3:$H$1981,$C2,門市請款明細表!$I$3:$I$1981,F$1) -> 0 | G2: =SUMIFS(門市請款明細表!$J$3:$J$1981,門市請款明細表!$H$3:$H$1981,$C2,門市請款明細表!$I$3:$I$1981,G$1) -> 0 | H2: =SUMIFS(門市請款明細表!$J$3:$J$1981,門市請款明細表!$H$3:$H$1981,$C2,門市請款明細表!$I$3:$I$1981,H$1) -> 0 | I2: =SUM(E2:H2) -> 0 | J2: =IF(D2=I2,"●","✖") -> ●
A3: 2 | B3: ZV1 | C3: 三重 | D3: =SUMIF(門市請款明細表!$H$3:$H$1981,$C3,門市請款明細表!$J$3:$J$1981) -> 0 | E3: =SUMIFS(門市請款明細表!$J$3:$J$1981,門市請款明細表!$H$3:$H$1981,$C3,門市請款明細表!$I$3:$I$1981,E$1) -> 0 | F3: =SUMIFS(門市請款明細表!$J$3:$J$1981,門市請款明細表!$H$3:$H$1981,$C3,門市請款明細表!$I$3:$I$1981,F$1) -> 0 | G3: =SUMIFS(門市請款明細表!$J$3:$J$1981,門市請款明細表!$H$3:$H$1981,$C3,門市請款明細表!$I$3:$I$1981,G$1) -> 0 | H3: =SUMIFS(門市請款明細表!$J$3:$J$1981,門市請款明細表!$H$3:$H$1981,$C3,門市請款明細表!$I$3:$I$1981,H$1) -> 0 | I3: =SUM(E3:H3) -> 0 | J3: =IF(D3=I3,"●","✖") -> ●
A4: 3 | B4: ZV1 | C4: 台北東區 | D4: =SUMIF(門市請款明細表!$H$3:$H$1981,$C4,門市請款明細表!$J$3:$J$1981) -> 0 | E4: =SUMIFS(門市請款明細表!$J$3:$J$1981,門市請款明細表!$H$3:$H$1981,$C4,門市請款明細表!$I$3:$I$1981,E$1) -> 0 | F4: =SUMIFS(門市請款明細表!$J$3:$J$1981,門市請款明細表!$H$3:$H$1981,$C4,門市請款明細表!$I$3:$I$1981,F$1) -> 0 | G4: =SUMIFS(門市請款明細表!$J$3:$J$1981,門市請款明細表!$H$3:$H$1981,$C4,門市請款明細表!$I$3:$I$1981,G$1) -> 0 | H4: =SUMIFS(門市請款明細表!$J$3:$J$1981,門市請款明細表!$H$3:$H$1981,$C4,門市請款明細表!$I$3:$I$1981,H$1) -> 0 | I4: =SUM(E4:H4) -> 0 | J4: =IF(D4=I4,"●","✖") -> ●
A5: 4 | B5: ZF | C5: 林森 | D5: =SUMIF(門市請款明細表!$H$3:$H$1981,$C5,門市請款明細表!$J$3:$J$1981) -> 0 | E5: =SUMIFS(門市請款明細表!$J$3:$J$1981,門市請款明細表!$H$3:$H$1981,$C5,門市請款明細表!$I$3:$I$1981,E$1) -> 0 | F5: =SUMIFS(門市請款明細表!$J$3:$J$1981,門市請款明細表!$H$3:$H$1981,$C5,門市請款明細表!$I$3:$I$1981,F$1) -> 0 | G5: =SUMIFS(門市請款明細表!$J$3:$J$1981,門市請款明細表!$H$3:$H$1981,$C5,門市請款明細表!$I$3:$I$1981,G$1) -> 0 | H5: =SUMIFS(門市請款明細表!$J$3:$J$1981,門市請款明細表!$H$3:$H$1981,$C5,門市請款明細表!$I$3:$I$1981,H$1) -> 0 | I5: =SUM(E5:H5) -> 0 | J5: =IF(D5=I5,"●","✖") -> ●
A6: 5 | B6: ZV1 | C6: 台北東門 | D6: =SUMIF(門市請款明細表!$H$3:$H$1981,$C6,門市請款明細表!$J$3:$J$1981) -> 0 | E6: =SUMIFS(門市請款明細表!$J$3:$J$1981,門市請款明細表!$H$3:$H$1981,$C6,門市請款明細表!$I$3:$I$1981,E$1) -> 0 | F6: =SUMIFS(門市請款明細表!$J$3:$J$1981,門市請款明細表!$H$3:$H$1981,$C6,門市請款明細表!$I$3:$I$1981,F$1) -> 0 | G6: =SUMIFS(門市請款明細表!$J$3:$J$1981,門市請款明細表!$H$3:$H$1981,$C6,門市請款明細表!$I$3:$I$1981,G$1) -> 0 | H6: =SUMIFS(門市請款明細表!$J$3:$J$1981,門市請款明細表!$H$3:$H$1981,$C6,門市請款明細表!$I$3:$I$1981,H$1) -> 0 | I6: =SUM(E6:H6) -> 0 | J6: =IF(D6=I6,"●","✖") -> ●
A7: 6 | B7: ZV1 | C7: 長春 | D7: =SUMIF(門市請款明細表!$H$3:$H$1981,$C7,門市請款明細表!$J$3:$J$1981) -> 0 | E7: =SUMIFS(門市請款明細表!$J$3:$J$1981,門市請款明細表!$H$3:$H$1981,$C7,門市請款明細表!$I$3:$I$1981,E$1) -> 0 | F7: =SUMIFS(門市請款明細表!$J$3:$J$1981,門市請款明細表!$H$3:$H$1981,$C7,門市請款明細表!$I$3:$I$1981,F$1) -> 0 | G7: =SUMIFS(門市請款明細表!$J$3:$J$1981,門市請款明細表!$H$3:$H$1981,$C7,門市請款明細表!$I$3:$I$1981,G$1) -> 0 | H7: =SUMIFS(門市請款明細表!$J$3:$J$1981,門市請款明細表!$H$3:$H$1981,$C7,門市請款明細表!$I$3:$I$1981,H$1) -> 0 | I7: =SUM(E7:H7) -> 0 | J7: =IF(D7=I7,"●","✖") -> ●
A8: 7 | B8: ZV1 | C8: 大坪林 | D8: =SUMIF(門市請款明細表!$H$3:$H$1981,$C8,門市請款明細表!$J$3:$J$1981) -> 0 | E8: =SUMIFS(門市請款明細表!$J$3:$J$1981,門市請款明細表!$H$3:$H$1981,$C8,門市請款明細表!$I$3:$I$1981,E$1) -> 0 | F8: =SUMIFS(門市請款明細表!$J$3:$J$1981,門市請款明細表!$H$3:$H$1981,$C8,門市請款明細表!$I$3:$I$1981,F$1) -> 0 | G8: =SUMIFS(門市請款明細表!$J$3:$J$1981,門市請款明細表!$H$3:$H$1981,$C8,門市請款明細表!$I$3:$I$1981,G$1) -> 0 | H8: =SUMIFS(門市請款明細表!$J$3:$J$1981,門市請款明細表!$H$3:$H$1981,$C8,門市請款明細表!$I$3:$I$1981,H$1) -> 0 | I8: =SUM(E8:H8) -> 0 | J8: =IF(D8=I8,"●","✖") -> ●
A9: 8 | B9: ZV1 | C9: 台北公館 | D9: =SUMIF(門市請款明細表!$H$3:$H$1981,$C9,門市請款明細表!$J$3:$J$1981) -> 0 | E9: =SUMIFS(門市請款明細表!$J$3:$J$1981,門市請款明細表!$H$3:$H$1981,$C9,門市請款明細表!$I$3:$I$1981,E$1) -> 0 | F9: =SUMIFS(門市請款明細表!$J$3:$J$1981,門市請款明細表!$H$3:$H$1981,$C9,門市請款明細表!$I$3:$I$1981,F$1) -> 0 | G9: =SUMIFS(門市請款明細表!$J$3:$J$1981,門市請款明細表!$H$3:$H$1981,$C9,門市請款明細表!$I$3:$I$1981,G$1) -> 0 | H9: =SUMIFS(門市請款明細表!$J$3:$J$1981,門市請款明細表!$H$3:$H$1981,$C9,門市請款明細表!$I$3:$I$1981,H$1) -> 0 | I9: =SUM(E9:H9) -> 0 | J9: =IF(D9=I9,"●","✖") -> ●
A10: 9 | B10: ZV1 | C10: 台北木新 | D10: =SUMIF(門市請款明細表!$H$3:$H$1981,$C10,門市請款明細表!$J$3:$J$1981) -> 0 | E10: =SUMIFS(門市請款明細表!$J$3:$J$1981,門市請款明細表!$H$3:$H$1981,$C10,門市請款明細表!$I$3:$I$1981,E$1) -> 0 | F10: =SUMIFS(門市請款明細表!$J$3:$J$1981,門市請款明細表!$H$3:$H$1981,$C10,門市請款明細表!$I$3:$I$1981,F$1) -> 0 | G10: =SUMIFS(門市請款明細表!$J$3:$J$1981,門市請款明細表!$H$3:$H$1981,$C10,門市請款明細表!$I$3:$I$1981,G$1) -> 0 | H10: =SUMIFS(門市請款明細表!$J$3:$J$1981,門市請款明細表!$H$3:$H$1981,$C10,門市請款明細表!$I$3:$I$1981,H$1) -> 0 | I10: =SUM(E10:H10) -> 0 | J10: =IF(D10=I10,"●","✖") -> ●
A11: 10 | B11: ZV1 | C11: 台北師大 | D11: =SUMIF(門市請款明細表!$H$3:$H$1981,$C11,門市請款明細表!$J$3:$J$1981) -> 0 | E11: =SUMIFS(門市請款明細表!$J$3:$J$1981,門市請款明細表!$H$3:$H$1981,$C11,門市請款明細表!$I$3:$I$1981,E$1) -> 0 | F11: =SUMIFS(門市請款明細表!$J$3:$J$1981,門市請款明細表!$H$3:$H$1981,$C11,門市請款明細表!$I$3:$I$1981,F$1) -> 0 | G11: =SUMIFS(門市請款明細表!$J$3:$J$1981,門市請款明細表!$H$3:$H$1981,$C11,門市請款明細表!$I$3:$I$1981,G$1) -> 0 | H11: =SUMIFS(門市請款明細表!$J$3:$J$1981,門市請款明細表!$H$3:$H$1981,$C11,門市請款明細表!$I$3:$I$1981,H$1) -> 0 | I11: =SUM(E11:H11) -> 0 | J11: =IF(D11=I11,"●","✖") -> ●
A12: 11 | B12: ZV1 | C12: 景文 | D12: =SUMIF(門市請款明細表!$H$3:$H$1981,$C12,門市請款明細表!$J$3:$J$1981) -> 0 | E12: =SUMIFS(門市請款明細表!$J$3:$J$1981,門市請款明細表!$H$3:$H$1981,$C12,門市請款明細表!$I$3:$I$1981,E$1) -> 0 | F12: =SUMIFS(門市請款明細表!$J$3:$J$1981,門市請款明細表!$H$3:$H$1981,$C12,門市請款明細表!$I$3:$I$1981,F$1) -> 0 | G12: =SUMIFS(門市請款明細表!$J$3:$J$1981,門市請款明細表!$H$3:$H$1981,$C12,門市請款明細表!$I$3:$I$1981,G$1) -> 0 | H12: =SUMIFS(門市請款明細表!$J$3:$J$1981,門市請款明細表!$H$3:$H$1981,$C12,門市請款明細表!$I$3:$I$1981,H$1) -> 0 | I12: =SUM(E12:H12) -> 0 | J12: =IF(D12=I12,"●","✖") -> ●
A13: 12 | B13: ZV1 | C13: 新店 | D13: =SUMIF(門市請款明細表!$H$3:$H$1981,$C13,門市請款明細表!$J$3:$J$1981) -> 0 | E13: =SUMIFS(門市請款明細表!$J$3:$J$1981,門市請款明細表!$H$3:$H$1981,$C13,門市請款明細表!$I$3:$I$1981,E$1) -> 0 | F13: =SUMIFS(門市請款明細表!$J$3:$J$1981,門市請款明細表!$H$3:$H$1981,$C13,門市請款明細表!$I$3:$I$1981,F$1) -> 0 | G13: =SUMIFS(門市請款明細表!$J$3:$J$1981,門市請款明細表!$H$3:$H$1981,$C13,門市請款明細表!$I$3:$I$1981,G$1) -> 0 | H13: =SUMIFS(門市請款明細表!$J$3:$J$1981,門市請款明細表!$H$3:$H$1981,$C13,門市請款明細表!$I$3:$I$1981,H$1) -> 0 | I13: =SUM(E13:H13) -> 0 | J13: =IF(D13=I13,"●","✖") -> ●
... A129: 128 | B129: ZC | C129: 大埔 | D129: =SUMIF(門市請款明細表!$H$3:$H$1981,$C129,門市請款明細表!$J$3:$J$1981) -> 0 | E129: =SUMIFS(門市請款明細表!$J$3:$J$1981,門市請款明細表!$H$3:$H$1981,$C129,門市請款明細表!$I$3:$I$1981,E$1) -> 0 | F129: =SUMIFS(門市請款明細表!$J$3:$J$1981,門市請款明細表!$H$3:$H$1981,$C129,門市請款明細表!$I$3:$I$1981,F$1) -> 0 | G129: =SUMIFS(門市請款明細表!$J$3:$J$1981,門市請款明細表!$H$3:$H$1981,$C129,門市請款明細表!$I$3:$I$1981,G$1) -> 0 | H129: =SUMIFS(門市請款明細表!$J$3:$J$1981,門市請款明細表!$H$3:$H$1981,$C129,門市請款明細表!$I$3:$I$1981,H$1) -> 0 | I129: =SUM(E129:H129) -> 0 | J129: =IF(D129=I129,"●","✖") -> ●
A130: 129 | C130: 天后 | D130: =SUMIF(門市請款明細表!$H$3:$H$1981,$C130,門市請款明細表!$J$3:$J$1981) -> 0 | E130: =SUMIFS(門市請款明細表!$J$3:$J$1981,門市請款明細表!$H$3:$H$1981,$C130,門市請款明細表!$I$3:$I$1981,E$1) -> 0 | F130: =SUMIFS(門市請款明細表!$J$3:$J$1981,門市請款明細表!$H$3:$H$1981,$C130,門市請款明細表!$I$3:$I$1981,F$1) -> 0 | G130: =SUMIFS(門市請款明細表!$J$3:$J$1981,門市請款明細表!$H$3:$H$1981,$C130,門市請款明細表!$I$3:$I$1981,G$1) -> 0 | H130: =SUMIFS(門市請款明細表!$J$3:$J$1981,門市請款明細表!$H$3:$H$1981,$C130,門市請款明細表!$I$3:$I$1981,H$1) -> 0 | I130: =SUM(E130:H130) -> 0 | J130: =IF(D130=I130,"●","✖") -> ●
A131: 130 | B131: ZC | C131: 斗南 | D131: =SUMIF(門市請款明細表!$H$3:$H$1981,$C131,門市請款明細表!$J$3:$J$1981) -> 0 | E131: =SUMIFS(門市請款明細表!$J$3:$J$1981,門市請款明細表!$H$3:$H$1981,$C131,門市請款明細表!$I$3:$I$1981,E$1) -> 0 | F131: =SUMIFS(門市請款明細表!$J$3:$J$1981,門市請款明細表!$H$3:$H$1981,$C131,門市請款明細表!$I$3:$I$1981,F$1) -> 0 | G131: =SUMIFS(門市請款明細表!$J$3:$J$1981,門市請款明細表!$H$3:$H$1981,$C131,門市請款明細表!$I$3:$I$1981,G$1) -> 0 | H131: =SUMIFS(門市請款明細表!$J$3:$J$1981,門市請款明細表!$H$3:$H$1981,$C131,門市請款明細表!$I$3:$I$1981,H$1) -> 0 | I131: =SUM(E131:H131) -> 0 | J131: =IF(D131=I131,"●","✖") -> ●
A132: 131 | B132: ZC | C132: 北斗 | D132: =SUMIF(門市請款明細表!$H$3:$H$1981,$C132,門市請款明細表!$J$3:$J$1981) -> 0 | E132: =SUMIFS(門市請款明細表!$J$3:$J$1981,門市請款明細表!$H$3:$H$1981,$C132,門市請款明細表!$I$3:$I$1981,E$1) -> 0 | F132: =SUMIFS(門市請款明細表!$J$3:$J$1981,門市請款明細表!$H$3:$H$1981,$C132,門市請款明細表!$I$3:$I$1981,F$1) -> 0 | G132: =SUMIFS(門市請款明細表!$J$3:$J$1981,門市請款明細表!$H$3:$H$1981,$C132,門市請款明細表!$I$3:$I$1981,G$1) -> 0 | H132: =SUMIFS(門市請款明細表!$J$3:$J$1981,門市請款明細表!$H$3:$H$1981,$C132,門市請款明細表!$I$3:$I$1981,H$1) -> 0 | I132: =SUM(E132:H132) -> 0 | J132: =IF(D132=I132,"●","✖") -> ●
A133: 132 | B133: ZC | C133: 永安 | D133: =SUMIF(門市請款明細表!$H$3:$H$1981,$C133,門市請款明細表!$J$3:$J$1981) -> 0 | E133: =SUMIFS(門市請款明細表!$J$3:$J$1981,門市請款明細表!$H$3:$H$1981,$C133,門市請款明細表!$I$3:$I$1981,E$1) -> 0 | F133: =SUMIFS(門市請款明細表!$J$3:$J$1981,門市請款明細表!$H$3:$H$1981,$C133,門市請款明細表!$I$3:$I$1981,F$1) -> 0 | G133: =SUMIFS(門市請款明細表!$J$3:$J$1981,門市請款明細表!$H$3:$H$1981,$C133,門市請款明細表!$I$3:$I$1981,G$1) -> 0 | H133: =SUMIFS(門市請款明細表!$J$3:$J$1981,門市請款明細表!$H$3:$H$1981,$C133,門市請款明細表!$I$3:$I$1981,H$1) -> 0 | I133: =SUM(E133:H133) -> 0 | J133: =IF(D133=I133,"●","✖") -> ●
A134: 133 | B134: ZC | C134: 虎科 | D134: =SUMIF(門市請款明細表!$H$3:$H$1981,$C134,門市請款明細表!$J$3:$J$1981) -> 0 | E134: =SUMIFS(門市請款明細表!$J$3:$J$1981,門市請款明細表!$H$3:$H$1981,$C134,門市請款明細表!$I$3:$I$1981,E$1) -> 0 | F134: =SUMIFS(門市請款明細表!$J$3:$J$1981,門市請款明細表!$H$3:$H$1981,$C134,門市請款明細表!$I$3:$I$1981,F$1) -> 0 | G134: =SUMIFS(門市請款明細表!$J$3:$J$1981,門市請款明細表!$H$3:$H$1981,$C134,門市請款明細表!$I$3:$I$1981,G$1) -> 0 | H134: =SUMIFS(門市請款明細表!$J$3:$J$1981,門市請款明細表!$H$3:$H$1981,$C134,門市請款明細表!$I$3:$I$1981,H$1) -> 0 | I134: =SUM(E134:H134) -> 0 | J134: =IF(D134=I134,"●","✖") -> ●
A135: 134 | B135: ZC | C135: 鹿港 | D135: =SUMIF(門市請款明細表!$H$3:$H$1981,$C135,門市請款明細表!$J$3:$J$1981) -> 0 | E135: =SUMIFS(門市請款明細表!$J$3:$J$1981,門市請款明細表!$H$3:$H$1981,$C135,門市請款明細表!$I$3:$I$1981,E$1) -> 0 | F135: =SUMIFS(門市請款明細表!$J$3:$J$1981,門市請款明細表!$H$3:$H$1981,$C135,門市請款明細表!$I$3:$I$1981,F$1) -> 0 | G135: =SUMIFS(門市請款明細表!$J$3:$J$1981,門市請款明細表!$H$3:$H$1981,$C135,門市請款明細表!$I$3:$I$1981,G$1) -> 0 | H135: =SUMIFS(門市請款明細表!$J$3:$J$1981,門市請款明細表!$H$3:$H$1981,$C135,門市請款明細表!$I$3:$I$1981,H$1) -> 0 | I135: =SUM(E135:H135) -> 0 | J135: =IF(D135=I135,"●","✖") -> ●
A136: 135 | B136: ZC | C136: 雲科 | D136: =SUMIF(門市請款明細表!$H$3:$H$1981,$C136,門市請款明細表!$J$3:$J$1981) -> 0 | E136: =SUMIFS(門市請款明細表!$J$3:$J$1981,門市請款明細表!$H$3:$H$1981,$C136,門市請款明細表!$I$3:$I$1981,E$1) -> 0 | F136: =SUMIFS(門市請款明細表!$J$3:$J$1981,門市請款明細表!$H$3:$H$1981,$C136,門市請款明細表!$I$3:$I$1981,F$1) -> 0 | G136: =SUMIFS(門市請款明細表!$J$3:$J$1981,門市請款明細表!$H$3:$H$1981,$C136,門市請款明細表!$I$3:$I$1981,G$1) -> 0 | H136: =SUMIFS(門市請款明細表!$J$3:$J$1981,門市請款明細表!$H$3:$H$1981,$C136,門市請款明細表!$I$3:$I$1981,H$1) -> 0 | I136: =SUM(E136:H136) -> 0 | J136: =IF(D136=I136,"●","✖") -> ●
A137: 136 | B137: ZC | C137: 彰師大 | D137: =SUMIF(門市請款明細表!$H$3:$H$1981,$C137,門市請款明細表!$J$3:$J$1981) -> 0 | E137: =SUMIFS(門市請款明細表!$J$3:$J$1981,門市請款明細表!$H$3:$H$1981,$C137,門市請款明細表!$I$3:$I$1981,E$1) -> 0 | F137: =SUMIFS(門市請款明細表!$J$3:$J$1981,門市請款明細表!$H$3:$H$1981,$C137,門市請款明細表!$I$3:$I$1981,F$1) -> 0 | G137: =SUMIFS(門市請款明細表!$J$3:$J$1981,門市請款明細表!$H$3:$H$1981,$C137,門市請款明細表!$I$3:$I$1981,G$1) -> 0 | H137: =SUMIFS(門市請款明細表!$J$3:$J$1981,門市請款明細表!$H$3:$H$1981,$C137,門市請款明細表!$I$3:$I$1981,H$1) -> 0 | I137: =SUM(E137:H137) -> 0 | J137: =IF(D137=I137,"●","✖") -> ●
A138: 137 | B138: ZC | C138: 靜修 | D138: =SUMIF(門市請款明細表!$H$3:$H$1981,$C138,門市請款明細表!$J$3:$J$1981) -> 0 | E138: =SUMIFS(門市請款明細表!$J$3:$J$1981,門市請款明細表!$H$3:$H$1981,$C138,門市請款明細表!$I$3:$I$1981,E$1) -> 0 | F138: =SUMIFS(門市請款明細表!$J$3:$J$1981,門市請款明細表!$H$3:$H$1981,$C138,門市請款明細表!$I$3:$I$1981,F$1) -> 0 | G138: =SUMIFS(門市請款明細表!$J$3:$J$1981,門市請款明細表!$H$3:$H$1981,$C138,門市請款明細表!$I$3:$I$1981,G$1) -> 0 | H138: =SUMIFS(門市請款明細表!$J$3:$J$1981,門市請款明細表!$H$3:$H$1981,$C138,門市請款明細表!$I$3:$I$1981,H$1) -> 0 | I138: =SUM(E138:H138) -> 0 | J138: =IF(D138=I138,"●","✖") -> ●
A139: 138 | B139: ZV2 | C139: 中壢 | D139: =SUMIF(門市請款明細表!$H$3:$H$1981,$C139,門市請款明細表!$J$3:$J$1981) -> 0 | E139: =SUMIFS(門市請款明細表!$J$3:$J$1981,門市請款明細表!$H$3:$H$1981,$C139,門市請款明細表!$I$3:$I$1981,E$1) -> 0 | F139: =SUMIFS(門市請款明細表!$J$3:$J$1981,門市請款明細表!$H$3:$H$1981,$C139,門市請款明細表!$I$3:$I$1981,F$1) -> 0 | G139: =SUMIFS(門市請款明細表!$J$3:$J$1981,門市請款明細表!$H$3:$H$1981,$C139,門市請款明細表!$I$3:$I$1981,G$1) -> 0 | H139: =SUMIFS(門市請款明細表!$J$3:$J$1981,門市請款明細表!$H$3:$H$1981,$C139,門市請款明細表!$I$3:$I$1981,H$1) -> 0 | I139: =SUM(E139:H139) -> 0 | J139: =IF(D139=I139,"●","✖") -> ●
A140: 139 | B140: ZE | C140: 台南中華 | D140: =SUMIF(門市請款明細表!$H$3:$H$1981,$C140,門市請款明細表!$J$3:$J$1981) -> 0 | E140: =SUMIFS(門市請款明細表!$J$3:$J$1981,門市請款明細表!$H$3:$H$1981,$C140,門市請款明細表!$I$3:$I$1981,E$1) -> 0 | F140: =SUMIFS(門市請款明細表!$J$3:$J$1981,門市請款明細表!$H$3:$H$1981,$C140,門市請款明細表!$I$3:$I$1981,F$1) -> 0 | G140: =SUMIFS(門市請款明細表!$J$3:$J$1981,門市請款明細表!$H$3:$H$1981,$C140,門市請款明細表!$I$3:$I$1981,G$1) -> 0 | H140: =SUMIFS(門市請款明細表!$J$3:$J$1981,門市請款明細表!$H$3:$H$1981,$C140,門市請款明細表!$I$3:$I$1981,H$1) -> 0 | I140: =SUM(E140:H140) -> 0 | J140: =IF(D140=I140,"●","✖") -> ●
A141: 140 | B141: ZE | C141: 台南成功 | D141: =SUMIF(門市請款明細表!$H$3:$H$1981,$C141,門市請款明細表!$J$3:$J$1981) -> 0 | E141: =SUMIFS(門市請款明細表!$J$3:$J$1981,門市請款明細表!$H$3:$H$1981,$C141,門市請款明細表!$I$3:$I$1981,E$1) -> 0 | F141: =SUMIFS(門市請款明細表!$J$3:$J$1981,門市請款明細表!$H$3:$H$1981,$C141,門市請款明細表!$I$3:$I$1981,F$1) -> 0 | G141: =SUMIFS(門市請款明細表!$J$3:$J$1981,門市請款明細表!$H$3:$H$1981,$C141,門市請款明細表!$I$3:$I$1981,G$1) -> 0 | H141: =SUMIFS(門市請款明細表!$J$3:$J$1981,門市請款明細表!$H$3:$H$1981,$C141,門市請款明細表!$I$3:$I$1981,H$1) -> 0 | I141: =SUM(E141:H141) -> 0 | J141: =IF(D141=I141,"●","✖") -> ●
A142: 141 | B142: ZE | C142: 台南東門 | D142: =SUMIF(門市請款明細表!$H$3:$H$1981,$C142,門市請款明細表!$J$3:$J$1981) -> 0 | E142: =SUMIFS(門市請款明細表!$J$3:$J$1981,門市請款明細表!$H$3:$H$1981,$C142,門市請款明細表!$I$3:$I$1981,E$1) -> 0 | F142: =SUMIFS(門市請款明細表!$J$3:$J$1981,門市請款明細表!$H$3:$H$1981,$C142,門市請款明細表!$I$3:$I$1981,F$1) -> 0 | G142: =SUMIFS(門市請款明細表!$J$3:$J$1981,門市請款明細表!$H$3:$H$1981,$C142,門市請款明細表!$I$3:$I$1981,G$1) -> 0 | H142: =SUMIFS(門市請款明細表!$J$3:$J$1981,門市請款明細表!$H$3:$H$1981,$C142,門市請款明細表!$I$3:$I$1981,H$1) -> 0 | I142: =SUM(E142:H142) -> 0 | J142: =IF(D142=I142,"●","✖") -> ●
... A187: 186 | B187: ZV2 | C187: 桃園國際機場(一航入) | D187: =SUMIF(門市請款明細表!$H$3:$H$1981,$C187,門市請款明細表!$J$3:$J$1981) -> 0 | E187: =SUMIFS(門市請款明細表!$J$3:$J$1981,門市請款明細表!$H$3:$H$1981,$C187,門市請款明細表!$I$3:$I$1981,E$1) -> 0 | F187: =SUMIFS(門市請款明細表!$J$3:$J$1981,門市請款明細表!$H$3:$H$1981,$C187,門市請款明細表!$I$3:$I$1981,F$1) -> 0 | G187: =SUMIFS(門市請款明細表!$J$3:$J$1981,門市請款明細表!$H$3:$H$1981,$C187,門市請款明細表!$I$3:$I$1981,G$1) -> 0 | H187: =SUMIFS(門市請款明細表!$J$3:$J$1981,門市請款明細表!$H$3:$H$1981,$C187,門市請款明細表!$I$3:$I$1981,H$1) -> 0 | I187: =SUM(E187:H187) -> 0 | J187: =IF(D187=I187,"●","✖") -> ●
B188: ZV2 | C188: 桃園國際機場(一航出) | D188: =SUMIF(門市請款明細表!$H$3:$H$1981,$C188,門市請款明細表!$J$3:$J$1981) -> 0 | E188: =SUMIFS(門市請款明細表!$J$3:$J$1981,門市請款明細表!$H$3:$H$1981,$C188,門市請款明細表!$I$3:$I$1981,E$1) -> 0 | F188: =SUMIFS(門市請款明細表!$J$3:$J$1981,門市請款明細表!$H$3:$H$1981,$C188,門市請款明細表!$I$3:$I$1981,F$1) -> 0 | G188: =SUMIFS(門市請款明細表!$J$3:$J$1981,門市請款明細表!$H$3:$H$1981,$C188,門市請款明細表!$I$3:$I$1981,G$1) -> 0 | H188: =SUMIFS(門市請款明細表!$J$3:$J$1981,門市請款明細表!$H$3:$H$1981,$C188,門市請款明細表!$I$3:$I$1981,H$1) -> 0 | I188: =SUM(E188:H188) -> 0 | J188: =IF(D188=I188,"●","✖") -> ●
B189: ZV2 | C189: 桃園國際機場(一航入管制區) | D189: =SUMIF(門市請款明細表!$H$3:$H$1981,$C189,門市請款明細表!$J$3:$J$1981) -> 0 | E189: =SUMIFS(門市請款明細表!$J$3:$J$1981,門市請款明細表!$H$3:$H$1981,$C189,門市請款明細表!$I$3:$I$1981,E$1) -> 0 | F189: =SUMIFS(門市請款明細表!$J$3:$J$1981,門市請款明細表!$H$3:$H$1981,$C189,門市請款明細表!$I$3:$I$1981,F$1) -> 0 | G189: =SUMIFS(門市請款明細表!$J$3:$J$1981,門市請款明細表!$H$3:$H$1981,$C189,門市請款明細表!$I$3:$I$1981,G$1) -> 0 | H189: =SUMIFS(門市請款明細表!$J$3:$J$1981,門市請款明細表!$H$3:$H$1981,$C189,門市請款明細表!$I$3:$I$1981,H$1) -> 0 | I189: =SUM(E189:H189) -> 0 | J189: =IF(D189=I189,"●","✖") -> ●
B190: ZV2 | C190: 桃園國際機場(二航出) | D190: =SUMIF(門市請款明細表!$H$3:$H$1981,$C190,門市請款明細表!$J$3:$J$1981) -> 0 | E190: =SUMIFS(門市請款明細表!$J$3:$J$1981,門市請款明細表!$H$3:$H$1981,$C190,門市請款明細表!$I$3:$I$1981,E$1) -> 0 | F190: =SUMIFS(門市請款明細表!$J$3:$J$1981,門市請款明細表!$H$3:$H$1981,$C190,門市請款明細表!$I$3:$I$1981,F$1) -> 0 | G190: =SUMIFS(門市請款明細表!$J$3:$J$1981,門市請款明細表!$H$3:$H$1981,$C190,門市請款明細表!$I$3:$I$1981,G$1) -> 0 | H190: =SUMIFS(門市請款明細表!$J$3:$J$1981,門市請款明細表!$H$3:$H$1981,$C190,門市請款明細表!$I$3:$I$1981,H$1) -> 0 | I190: =SUM(E190:H190) -> 0 | J190: =IF(D190=I190,"●","✖") -> ●
B191: ZV2 | C191: 桃園國際機場(二航入) | D191: =SUMIF(門市請款明細表!$H$3:$H$1981,$C191,門市請款明細表!$J$3:$J$1981) -> 0 | E191: =SUMIFS(門市請款明細表!$J$3:$J$1981,門市請款明細表!$H$3:$H$1981,$C191,門市請款明細表!$I$3:$I$1981,E$1) -> 0 | F191: =SUMIFS(門市請款明細表!$J$3:$J$1981,門市請款明細表!$H$3:$H$1981,$C191,門市請款明細表!$I$3:$I$1981,F$1) -> 0 | G191: =SUMIFS(門市請款明細表!$J$3:$J$1981,門市請款明細表!$H$3:$H$1981,$C191,門市請款明細表!$I$3:$I$1981,G$1) -> 0 | H191: =SUMIFS(門市請款明細表!$J$3:$J$1981,門市請款明細表!$H$3:$H$1981,$C191,門市請款明細表!$I$3:$I$1981,H$1) -> 0 | I191: =SUM(E191:H191) -> 0 | J191: =IF(D191=I191,"●","✖") -> ●
A192: 187 | C192: 北台中辦公室 | D192: =SUMIF(門市請款明細表!$H$3:$H$1981,$C192,門市請款明細表!$J$3:$J$1981) -> 0 | E192: =SUMIFS(門市請款明細表!$J$3:$J$1981,門市請款明細表!$H$3:$H$1981,$C192,門市請款明細表!$I$3:$I$1981,E$1) -> 0 | F192: =SUMIFS(門市請款明細表!$J$3:$J$1981,門市請款明細表!$H$3:$H$1981,$C192,門市請款明細表!$I$3:$I$1981,F$1) -> 0 | G192: =SUMIFS(門市請款明細表!$J$3:$J$1981,門市請款明細表!$H$3:$H$1981,$C192,門市請款明細表!$I$3:$I$1981,G$1) -> 0 | H192: =SUMIFS(門市請款明細表!$J$3:$J$1981,門市請款明細表!$H$3:$H$1981,$C192,門市請款明細表!$I$3:$I$1981,H$1) -> 0 | I192: =SUM(E192:H192) -> 0 | J192: =IF(D192=I192,"●","✖") -> ●
A193: 188 | B193: Z25-客 | C193: 高雄辦公室 | D193: =SUMIF(門市請款明細表!$H$3:$H$1981,$C193,門市請款明細表!$J$3:$J$1981) -> 0 | E193: =SUMIFS(門市請款明細表!$J$3:$J$1981,門市請款明細表!$H$3:$H$1981,$C193,門市請款明細表!$I$3:$I$1981,E$1) -> 0 | F193: =SUMIFS(門市請款明細表!$J$3:$J$1981,門市請款明細表!$H$3:$H$1981,$C193,門市請款明細表!$I$3:$I$1981,F$1) -> 0 | G193: =SUMIFS(門市請款明細表!$J$3:$J$1981,門市請款明細表!$H$3:$H$1981,$C193,門市請款明細表!$I$3:$I$1981,G$1) -> 0 | H193: =SUMIFS(門市請款明細表!$J$3:$J$1981,門市請款明細表!$H$3:$H$1981,$C193,門市請款明細表!$I$3:$I$1981,H$1) -> 0 | I193: =SUM(E193:H193) -> 0 | J193: =IF(D193=I193,"●","✖") -> ●
A194: 189 | B194: ZV1 | C194: 七堵 | D194: =SUMIF(門市請款明細表!$H$3:$H$1981,$C194,門市請款明細表!$J$3:$J$1981) -> 0 | E194: =SUMIFS(門市請款明細表!$J$3:$J$1981,門市請款明細表!$H$3:$H$1981,$C194,門市請款明細表!$I$3:$I$1981,E$1) -> 0 | F194: =SUMIFS(門市請款明細表!$J$3:$J$1981,門市請款明細表!$H$3:$H$1981,$C194,門市請款明細表!$I$3:$I$1981,F$1) -> 0 | G194: =SUMIFS(門市請款明細表!$J$3:$J$1981,門市請款明細表!$H$3:$H$1981,$C194,門市請款明細表!$I$3:$I$1981,G$1) -> 0 | H194: =SUMIFS(門市請款明細表!$J$3:$J$1981,門市請款明細表!$H$3:$H$1981,$C194,門市請款明細表!$I$3:$I$1981,H$1) -> 0 | I194: =SUM(E194:H194) -> 0 | J194: =IF(D194=I194,"●","✖") -> ●
A195: 190 | B195: ZC | C195: 和美 | D195: =SUMIF(門市請款明細表!$H$3:$H$1981,$C195,門市請款明細表!$J$3:$J$1981) -> 0 | E195: =SUMIFS(門市請款明細表!$J$3:$J$1981,門市請款明細表!$H$3:$H$1981,$C195,門市請款明細表!$I$3:$I$1981,E$1) -> 0 | F195: =SUMIFS(門市請款明細表!$J$3:$J$1981,門市請款明細表!$H$3:$H$1981,$C195,門市請款明細表!$I$3:$I$1981,F$1) -> 0 | G195: =SUMIFS(門市請款明細表!$J$3:$J$1981,門市請款明細表!$H$3:$H$1981,$C195,門市請款明細表!$I$3:$I$1981,G$1) -> 0 | H195: =SUMIFS(門市請款明細表!$J$3:$J$1981,門市請款明細表!$H$3:$H$1981,$C195,門市請款明細表!$I$3:$I$1981,H$1) -> 0 | I195: =SUM(E195:H195) -> 0 | J195: =IF(D195=I195,"●","✖") -> ●
A196: 191 | B196: ZC | C196: 林內 | D196: =SUMIF(門市請款明細表!$H$3:$H$1981,$C196,門市請款明細表!$J$3:$J$1981) -> 0 | E196: =SUMIFS(門市請款明細表!$J$3:$J$1981,門市請款明細表!$H$3:$H$1981,$C196,門市請款明細表!$I$3:$I$1981,E$1) -> 0 | F196: =SUMIFS(門市請款明細表!$J$3:$J$1981,門市請款明細表!$H$3:$H$1981,$C196,門市請款明細表!$I$3:$I$1981,F$1) -> 0 | G196: =SUMIFS(門市請款明細表!$J$3:$J$1981,門市請款明細表!$H$3:$H$1981,$C196,門市請款明細表!$I$3:$I$1981,G$1) -> 0 | H196: =SUMIFS(門市請款明細表!$J$3:$J$1981,門市請款明細表!$H$3:$H$1981,$C196,門市請款明細表!$I$3:$I$1981,H$1) -> 0 | I196: =SUM(E196:H196) -> 0 | J196: =IF(D196=I196,"●","✖") -> ●
A197: 192 | B197: ZC | C197: 大埤 | D197: =SUMIF(門市請款明細表!$H$3:$H$1981,$C197,門市請款明細表!$J$3:$J$1981) -> 0 | E197: =SUMIFS(門市請款明細表!$J$3:$J$1981,門市請款明細表!$H$3:$H$1981,$C197,門市請款明細表!$I$3:$I$1981,E$1) -> 0 | F197: =SUMIFS(門市請款明細表!$J$3:$J$1981,門市請款明細表!$H$3:$H$1981,$C197,門市請款明細表!$I$3:$I$1981,F$1) -> 0 | G197: =SUMIFS(門市請款明細表!$J$3:$J$1981,門市請款明細表!$H$3:$H$1981,$C197,門市請款明細表!$I$3:$I$1981,G$1) -> 0 | H197: =SUMIFS(門市請款明細表!$J$3:$J$1981,門市請款明細表!$H$3:$H$1981,$C197,門市請款明細表!$I$3:$I$1981,H$1) -> 0 | I197: =SUM(E197:H197) -> 0 | J197: =IF(D197=I197,"●","✖") -> ●
A198: 193 | B198: ZC | C198: 崙背 | D198: =SUMIF(門市請款明細表!$H$3:$H$1981,$C198,門市請款明細表!$J$3:$J$1981) -> 0 | E198: =SUMIFS(門市請款明細表!$J$3:$J$1981,門市請款明細表!$H$3:$H$1981,$C198,門市請款明細表!$I$3:$I$1981,E$1) -> 0 | F198: =SUMIFS(門市請款明細表!$J$3:$J$1981,門市請款明細表!$H$3:$H$1981,$C198,門市請款明細表!$I$3:$I$1981,F$1) -> 0 | G198: =SUMIFS(門市請款明細表!$J$3:$J$1981,門市請款明細表!$H$3:$H$1981,$C198,門市請款明細表!$I$3:$I$1981,G$1) -> 0 | H198: =SUMIFS(門市請款明細表!$J$3:$J$1981,門市請款明細表!$H$3:$H$1981,$C198,門市請款明細表!$I$3:$I$1981,H$1) -> 0 | I198: =SUM(E198:H198) -> 0 | J198: =IF(D198=I198,"●","✖") -> ●
A199: 194 | B199: ZC | C199: 莿桐 | D199: =SUMIF(門市請款明細表!$H$3:$H$1981,$C199,門市請款明細表!$J$3:$J$1981) -> 0 | E199: =SUMIFS(門市請款明細表!$J$3:$J$1981,門市請款明細表!$H$3:$H$1981,$C199,門市請款明細表!$I$3:$I$1981,E$1) -> 0 | F199: =SUMIFS(門市請款明細表!$J$3:$J$1981,門市請款明細表!$H$3:$H$1981,$C199,門市請款明細表!$I$3:$I$1981,F$1) -> 0 | G199: =SUMIFS(門市請款明細表!$J$3:$J$1981,門市請款明細表!$H$3:$H$1981,$C199,門市請款明細表!$I$3:$I$1981,G$1) -> 0 | H199: =SUMIFS(門市請款明細表!$J$3:$J$1981,門市請款明細表!$H$3:$H$1981,$C199,門市請款明細表!$I$3:$I$1981,H$1) -> 0 | I199: =SUM(E199:H199) -> 0 | J199: =IF(D199=I199,"●","✖") -> ●
...

Sheet 客編設定
A2: A | B2: 台北 | C2: N | D2: 彰化
A3: B | B3: 台中 | C3: O | D3: 新竹市
A4: C | B4: 基隆 | C4: P | D4: 雲林
A5: D | B5: 台南 | C5: Q | D5: 嘉義縣
A6: E | B6: 高雄 | C6: R | D6: 管理
A7: F | B7: 新北 | C7: S | D7: 行銷
A8: G | B8: 宜蘭 | C8: T | D8: 屏東
A9: H | B9: 桃園 | C9: U | D9: 花蓮
A10: I | B10: 嘉義市 | C10: V | D10: 台東
A11: J | B11: 新竹縣 | C11: W | D11: 金門
A12: K | B12: 苗栗 | C12: X | D12: 澎湖
A13: L | B13: 通路營運 | C13: Y
A14: M | B14: 南投 | C14: Z | D14: 連江
A16: 1~6 | B16: 營業處
A17: 7 | B17: 通路

Sheet 合約與計費
A2: 項次 | B2: 項目名稱 | C2: 租賃數量 | D2: 列印單價(含稅) | F2: 備註
D3: 黑白單張 | E3: 彩色單張
A4: 1 | B4: (黑白)單功能事務機 型號: 環章編號: | C4: 1280 | D4: 0.296 | E4: 2.8 | F4: 事務機計數器跳表次數之計算，不論紙張大小、黑白或彩色，每次影印一律以每張(1次)計數(單面計數1次，雙面計數2次)
A5: 2 | B5: (黑白)多功能事務機 型號: 環章編號: | C5: 304
A6: 3 | B6: (彩色)多功能事務機 型號: 環章編號: | C6: 376
A7: 4年(48個月)總金額合計新臺幣 | E7: 27069555 | G7: 元
A9: 合約期間:裝機日至118年1月4日，後續續約1年。
A11: 案 號：113GA011號於114年1月16日開標，自決標日起至118年1月4日止，共48期，無論實際裝機時間長短，
A12: 本契約租賃期間屆滿即所有機台停止租賃，如雙方合作良好，本公司得視需求於契約屆滿前30日通知得標
A13: 廠商依本契約相同條件續約一年，並以一次為限。
A15: *計費方式:無月租費，列印實印實收需扣誤印率3%，主機板故障取前三個月平均用量。
A16: *每月5日前提供請款資料(工程師抄表單電子檔、用量頁電子檔、Excel表)給李欣慈，20日開電子發票e-mail:carali@honghwa.com.tw李欣慈。
A17: *人損另報價李欣慈，口頭告知機器進水或蟑螂機不維修以換機處理。
A18: *長假或過年提供值班表。
A19: *年底會提早關帳，要確認開發票時間。
A20: *空匣需工程師抄表回收，遺失空匣支付300元未稅。
A21: 遺失全新碳粉匣依照"共同共應契約的公告價格"收費。(114/3/5 jason e-mail欣慈)
A22: *danny提出希望閉點或移機請提早半個月通知。
A23: *全案驗收提供裝機確認書+初始用量頁電子檔免紙本，裝機確認書+初始用量頁為一組，多台即照順序掃在一起，門市為一個檔案，安裝完畢一次給(以處、部區分)。

Sheet DPCache_1968台
A1: 序號 | B1: 設備編號 | C1: 門市 | D1: 機型 | E1: 惠傑申請型號 | F1: 現有型號 | G1: 營運別 | H1: 部別 | I1: 地址 | J1: 電話 | K1: 營業時間 | L1: 備註
A2: 1 | B2: AT701 | C2: 基隆 | D2: L6400DW | E2: 黑白單功能 | F2: 黑白單功能 | G2: 營運二處 | H2: 基隆部 | I2: 基隆市仁愛區仁一路321號 | J2: 02-24210467 | K2: 週一至週五 09:00~21:00 週六至週日 13:00~21:00
A3: 2 | B3: AT704 | C3: 基隆 | D3: L6400DW | E3: 黑白單功能 | F3: 黑白單功能 | G3: 營運二處 | H3: 基隆部 | I3: 基隆市仁愛區仁一路321號 | J3: 02-24210467 | K3: 週一至週五 09:00~21:00 週六至週日 13:00~21:00
A4: 3 | B4: AT705 | C4: 基隆 | D4: L6400DW | E4: 黑白單功能 | F4: 黑白單功能 | G4: 營運二處 | H4: 基隆部 | I4: 基隆市仁愛區仁一路321號 | J4: 02-24210467 | K4: 週一至週五 09:00~21:00 週六至週日 13:00~21:00
A5: 4 | B5: AT706 | C5: 基隆 | D5: L6400DW | E5: 黑白單功能 | F5: 黑白單功能 | G5: 營運二處 | H5: 基隆部 | I5: 基隆市仁愛區仁一路321號 | J5: 02-24210467 | K5: 週一至週五 09:00~21:00 週六至週日 13:00~21:00
A6: 5 | B6: AT707 | C6: 基隆 | D6: L6400DW | E6: 黑白單功能 | F6: 黑白單功能 | G6: 營運二處 | H6: 基隆部 | I6: 基隆市仁愛區仁一路321號 | J6: 02-24210467 | K6: 週一至週五 09:00~21:00 週六至週日 13:00~21:00
A7: 6 | B7: AT708 | C7: 基隆 | D7: L6400DW | E7: 黑白單功能 | F7: 黑白單功能 | G7: 營運二處 | H7: 基隆部 | I7: 基隆市仁愛區仁一路321號 | J7: 02-24210467 | K7: 週一至週五 09:00~21:00 週六至週日 13:00~21:00
A8: 7 | B8: AT709 | C8: 基隆 | D8: L6400DW | E8: 黑白單功能 | F8: 黑白單功能 | G8: 營運二處 | H8: 基隆部 | I8: 基隆市仁愛區仁一路321號 | J8: 02-24210467 | K8: 週一至週五 09:00~21:00 週六至週日 13:00~21:00
A9: 8 | B9: AT710 | C9: 基隆 | D9: L6400DW | E9: 黑白單功能 | F9: 黑白單功能 | G9: 營運二處 | H9: 基隆部 | I9: 基隆市仁愛區仁一路321號 | J9: 02-24210467 | K9: 週一至週五 09:00~21:00 週六至週日 13:00~21:00
A10: 9 | B10: AT711 | C10: 基隆 | D10: L6400DW | E10: 黑白單功能 | F10: 黑白單功能 | G10: 營運二處 | H10: 基隆部 | I10: 基隆市仁愛區仁一路321號 | J10: 02-24210467 | K10: 週一至週五 09:00~21:00 週六至週日 13:00~21:00
A11: 10 | B11: AT712 | C11: 基隆 | D11: L6400DW | E11: 黑白單功能 | F11: 黑白單功能 | G11: 營運二處 | H11: 基隆部 | I11: 基隆市仁愛區仁一路321號 | J11: 02-24210467 | K11: 週一至週五 09:00~21:00 週六至週日 13:00~21:00
A12: 11 | B12: AT713 | C12: 基隆 | D12: L6400DW | E12: 黑白單功能 | F12: 黑白單功能 | G12: 營運二處 | H12: 基隆部 | I12: 基隆市仁愛區仁一路321號 | J12: 02-24210467 | K12: 週一至週五 09:00~21:00 週六至週日 13:00~21:00
A13: 12 | B13: AT714 | C13: 基隆 | D13: L6400DW | E13: 黑白單功能 | F13: 黑白單功能 | G13: 營運二處 | H13: 基隆部 | I13: 基隆市仁愛區仁一路321號 | J13: 02-24210467 | K13: 週一至週五 09:00~21:00 週六至週日 13:00~21:00
... A170: 169 | B170: AT006 | C170: 台北公園 | D170: L3750CDW | E170: 彩色多功能 | F170: 彩色多功能 | G170: 營運一處 | H170: 台北二部 | I170: 台北市中正區公園路18號 | J170: 02-23708688 | K170: 週一至週日11:00~21:00
A171: 170 | B171: AT007 | C171: 台北公園 | D171: L6900DW | E171: 黑白多功能 | F171: 黑白多功能 | G171: 營運一處 | H171: 台北二部 | I171: 台北市中正區公園路18號 | J171: 02-23708688 | K171: 週一至週日11:00~21:00 | L171: 測機安裝門市
A172: 171 | B172: AT008 | C172: 台北公園 | D172: L6400DW | E172: 黑白單功能 | F172: 黑白單功能 | G172: 營運一處 | H172: 台北二部 | I172: 台北市中正區公園路18號 | J172: 02-23708688 | K172: 週一至週日11:00~21:00 | L172: 測機安裝門市
A173: 172 | B173: AT009 | C173: 台北公園 | D173: L6400DW | E173: 黑白單功能 | F173: 黑白單功能 | G173: 營運一處 | H173: 台北二部 | I173: 台北市中正區公園路18號 | J173: 02-23708688 | K173: 週一至週日11:00~21:00
A174: 173 | B174: AT010 | C174: 台北公園 | D174: L6400DW | E174: 黑白單功能 | F174: 黑白單功能 | G174: 營運一處 | H174: 台北二部 | I174: 台北市中正區公園路18號 | J174: 02-23708688 | K174: 週一至週日11:00~21:00
A175: 174 | B175: AT011 | C175: 台北公園 | D175: L6400DW | E175: 黑白單功能 | F175: 黑白單功能 | G175: 營運一處 | H175: 台北二部 | I175: 台北市中正區公園路18號 | J175: 02-23708688 | K175: 週一至週日11:00~21:00
A176: 175 | B176: AT193 | C176: 台北南區 | D176: L6400DW | E176: 黑白單功能 | F176: 黑白單功能 | G176: 營運一處 | H176: 台北一部 | I176: 台北市中正區仁愛路一段42號 | J176: 02-23442475 | K176: 週一至週六09:00~18:00
A177: 176 | B177: AT195 | C177: 台北南區 | D177: L6400DW | E177: 黑白單功能 | F177: 黑白單功能 | G177: 營運一處 | H177: 台北一部 | I177: 台北市中正區仁愛路一段42號 | J177: 02-23442475 | K177: 週一至週六09:00~18:00
A178: 177 | B178: AT196 | C178: 台北南區 | D178: L6400DW | E178: 黑白單功能 | F178: 黑白單功能 | G178: 營運一處 | H178: 台北一部 | I178: 台北市中正區仁愛路一段42號 | J178: 02-23442475 | K178: 週一至週六09:00~18:00
A179: 178 | B179: AT197 | C179: 台北南區 | D179: L6400DW | E179: 黑白單功能 | F179: 黑白單功能 | G179: 營運一處 | H179: 台北一部 | I179: 台北市中正區仁愛路一段42號 | J179: 02-23442475 | K179: 週一至週六09:00~18:00
A180: 179 | B180: AT198 | C180: 台北南區 | D180: L6400DW | E180: 黑白單功能 | F180: 黑白單功能 | G180: 營運一處 | H180: 台北一部 | I180: 台北市中正區仁愛路一段42號 | J180: 02-23442475 | K180: 週一至週六09:00~18:00
A181: 180 | B181: AT199 | C181: 台北南區 | D181: L6400DW | E181: 黑白單功能 | F181: 黑白單功能 | G181: 營運一處 | H181: 台北一部 | I181: 台北市中正區仁愛路一段42號 | J181: 02-23442475 | K181: 週一至週六09:00~18:00
A182: 181 | B182: AT200 | C182: 台北南區 | D182: L6400DW | E182: 黑白單功能 | F182: 黑白單功能 | G182: 營運一處 | H182: 台北一部 | I182: 台北市中正區仁愛路一段42號 | J182: 02-23442475 | K182: 週一至週六09:00~18:00
A183: 182 | B183: AT231 | C183: 台北南區 | D183: L6400DW | E183: 黑白單功能 | F183: 黑白單功能 | G183: 營運一處 | H183: 台北一部 | I183: 台北市中正區仁愛路一段42號 | J183: 02-23442475 | K183: 週一至週六09:00~18:00
A184: 183 | B184: AT232 | C184: 台北南區 | D184: L6400DW | E184: 黑白單功能 | F184: 黑白單功能 | G184: 營運一處 | H184: 台北一部 | I184: 台北市中正區仁愛路一段42號 | J184: 02-23442475 | K184: 週一至週六09:00~18:00
... A741: 740 | B741: AQ390 | C741: 豐原中山 | D741: L6400DW | E741: 黑白單功能 | F741: 黑白單功能 | G741: 營運四處 | H741: 中三部 | I741: 台中市豐原區中山路412號 | J741: 04-25123414 | K741: 週一至週日11:00~21:00
A742: 741 | B742: AQ370 | C742: 大墩 | D742: L6400DW | E742: 黑白單功能 | F742: 黑白單功能 | G742: 營運四處 | H742: 中四部 | I742: 台中市西屯區大墩路932號 | J742: 04-23282098 | K742: 週一至週日13:00~21:00 | L742: 優先汰換
A743: 742 | B743: AQ371 | C743: 大墩 | D743: L6900DW | E743: 黑白多功能 | F743: 黑白多功能 | G743: 營運四處 | H743: 中四部 | I743: 台中市西屯區大墩路932號 | J743: 04-23282098 | K743: 週一至週日13:00~21:00 | L743: 優先汰換
A744: 743 | B744: AQ372 | C744: 大墩 | D744: L6400DW | E744: 黑白單功能 | F744: 黑白單功能 | G744: 營運四處 | H744: 中四部 | I744: 台中市西屯區大墩路932號 | J744: 04-23282098 | K744: 週一至週日13:00~21:00 | L744: 優先汰換
A745: 744 | B745: AQ373 | C745: 大墩 | D745: L3750CDW | E745: 彩色多功能 | F745: 彩色多功能 | G745: 營運四處 | H745: 中四部 | I745: 台中市西屯區大墩路932號 | J745: 04-23282098 | K745: 週一至週日13:00~21:00 | L745: 優先汰換
A746: 745 | B746: AQ352 | C746: 北台中 | D746: L6400DW | E746: 黑白單功能 | F746: 黑白單功能 | G746: 營運四處 | H746: 中一部 | I746: 台中市北區中清路一段347號 | J746: 04-23445236 | K746: 週一至週六08:30~18:30
A747: 746 | B747: AQ353 | C747: 北台中 | D747: L6400DW | E747: 黑白單功能 | F747: 黑白單功能 | G747: 營運四處 | H747: 中一部 | I747: 台中市北區中清路一段347號 | J747: 04-23445236 | K747: 週一至週六08:30~18:30
A748: 747 | B748: AQ354 | C748: 北台中 | D748: L6400DW | E748: 黑白單功能 | F748: 黑白單功能 | G748: 營運四處 | H748: 中一部 | I748: 台中市北區中清路一段347號 | J748: 04-23445236 | K748: 週一至週六08:30~18:30
A749: 748 | B749: AQ355 | C749: 北台中 | D749: L6400DW | E749: 黑白單功能 | F749: 黑白單功能 | G749: 營運四處 | H749: 中一部 | I749: 台中市北區中清路一段347號 | J749: 04-23445236 | K749: 週一至週六08:30~18:30
A750: 749 | B750: AQ356 | C750: 北台中 | D750: L6400DW | E750: 黑白單功能 | F750: 黑白單功能 | G750: 營運四處 | H750: 中一部 | I750: 台中市北區中清路一段347號 | J750: 04-23445236 | K750: 週一至週六08:30~18:30
A751: 750 | B751: AQ358 | C751: 北台中 | D751: L6400DW | E751: 黑白單功能 | F751: 黑白單功能 | G751: 營運四處 | H751: 中一部 | I751: 台中市北區中清路一段347號 | J751: 04-23445236 | K751: 週一至週六08:30~18:30
A752: 751 | B752: AQ359 | C752: 北台中 | D752: L6900DW | E752: 黑白多功能 | F752: 黑白多功能 | G752: 營運四處 | H752: 中一部 | I752: 台中市北區中清路一段347號 | J752: 04-23445236 | K752: 週一至週六08:30~18:30
...
